Workbook
Name L_所属: '選択肢'!$A$5:$A$20
Name L_在籍: '選択肢'!$B$5:$B$20
Name L_区分: '選択肢'!$C$5:$C$20
Name L_資格名: '選択肢'!$D$5:$D$20
Name L_種別: '選択肢'!$E$5:$E$20
Name L_地点: '選択肢'!$F$5:$F$20
Name L_有無: '選択肢'!$G$5:$G$20
Name L_抽出区分: '選択肢'!$H$5:$H$15
Name L_職員番号: '隊員マスタ'!$A$5:$A$204
Name L_事案ID: '事案'!$A$5:$A$1004

Sheet 使い方
A1: 潜水管理台帳 第2版
A2: 宮古島市消防本部 潜水隊。Excel 2019対応。一覧と集計は数式だけで動き、マクロは取り込み・書き出し用。氏名・数値はすべて見本です。
A4: 見る（自動）
A5: 隊員一覧 | B5: 1人1行。免許・研修・小型船舶・潜水本数・ブランクを一覧表示。太字は要確認
A6: 資格一覧 | B6: 隊員×資格の○—表
A7: 経歴簿 | B7: 職員番号を選ぶと、その人の潜水歴と累計が並ぶ。PDFで出せる
A8: 報告書 | B8: 事案IDを選ぶと、潜水活動報告書が1枚にまとまる。PDFで出し、指揮者が確認して署名する
A9: CSV抽出 | B9: 期間・区分・職員番号で潜水記録を絞り込み、CSVで出す
A11: 入力する
A12: 潜水記録・事案 | B12: アプリのCSVを取り込むと自動で入る。手で入力もできる。右端（AL列から）はアプリの追加記録（記録ID・浮上開始時刻・安全停止など）
A13: 隊員マスタ | B13: 1人1行。職員番号は重複不可（0で始まる番号もそのまま入る）。異動・退職しても行は消さず在籍状態を変える
A14: 資格研修記録 | B14: 1件1行。小型船舶は級ごとに1行（1級と特殊なら2行）
A15: 潜水表 | B15: アプリの潜水表の正本。直したら2人で照合し［アプリ用に書き出す］
A16: 選択肢 | B16: プルダウンの中身
A18: アプリの記録を取り込む
A19: 1 | B19: 現場用スマホから届いたメールのCSVを、パソコンに保存する（ダブルクリックでExcelで開かない。開いて上書き保存すると文字や番号が変わるので、取り込めなくなる）
A20: 2 | B20: 潜水記録シートの［アプリのCSVを取り込む］→ CSVを選ぶ（複数選べる）
A21: 3 | B21: 同じ潜水（記録IDが同じ。記録IDのない古いCSVは 事案ID・職員番号・本数が同じ）は二重に入らない。CSVの記録更新日時が台帳より新しいときだけ上書き（更新）・削除する。同じか古いCSVを取り込み直しても、署で手で直した内容は変わらない。アプリで削除した記録は行が空き、記録IDだけ残る（古いCSVで戻らないように。まだ台帳にない記録の削除も、この印の行を作る）
A22: 4 | B22: 報告書シートで事案IDを選び［報告書をPDF］→ 印刷して指揮者が確認・署名する
A24: 潜水表をアプリに送る
A25: 1 | B25: 潜水表シートの数値を直し、2人で照合して「照合」欄を照合済みにする
A26: 2 | B26: ［アプリ用に書き出す］→「出力」フォルダに .json ができる
A27: 3 | B27: その .json を現場用スマホへメールで送り、アプリの 潜水表 →［潜水表ファイルを読み込む］
A29: マクロの組み込み（初回だけ）
A30: 1 | B30: このファイルを［名前を付けて保存］→ 種類「Excel マクロ有効ブック（.xlsm）」。保存先はパソコンの中（例：ドキュメント）。OneDrive上のままではPDFや書き出しができない
A31: 2 | B31: Alt＋F11 → 左のプロジェクト一覧で「VBAProject (潜水管理台帳.xlsm)」をクリックして選ぶ →［ファイル］→［ファイルのインポート］→ 潜水管理マクロ.bas（別のブックを選んだまま取り込むと、そのブックに入ってしまう）
A32: 3 | B32: Alt＋F8 →「SetupButtons」を実行。各シートにボタンが付く
A33: 4 | B33: 上書き保存。次回から開くときに［コンテンツの有効化］
A35: 注意
A36: 判定 | B36: アプリの判定（表の判定・グループなど）はNAUI潜水表による計算の目安。実際の判断は指揮者とダイブコンピュータを優先する
A37: 記録の保存 | B37: 作業の記録は5年間保存（高圧則 第20条の2）。潜水記録・事案の行は消さず、この台帳ごと保存しておく
A38: CSVのメール | B38: メールの設定によっては、CSVの添付が消えたり迷惑メールに入ったりする。届いたら添付の有無と件数を確かめ、無いときはアプリから送り直す（アプリには記録が残っている）
A39: Excelで開いたCSV | B39: Excelで開いて上書き保存したCSVは取り込まない（「Excelで保存し直したCSVです」と出る）。メールで届いた元のファイルを使う
A40: 上限 | B40: 隊員200人、資格研修記録1000件、潜水記録3000件、事案1000件まで。経歴簿は1人300本、報告書は1事案30本まで表示（超えるとPDFを作るときに知らせる）

Sheet 隊員一覧
A1: 隊員一覧
A2: 基準日 | B2: =TODAY() | C2: 年度 | D2: =YEAR(EDATE(B2,-3)) | F2: このシートは自動表示です。入力は「隊員マスタ」「資格研修記録」「潜水記録」へ。
A4: 在籍隊員 | C4: 潜水士免許 保有 | F4: 小型船舶 保有（有効） | H4: 今年度 潜水本数
A5: =COUNTIF($D$8:$D$207,"在籍") | C5: =COUNTIFS($D$8:$D$207,"在籍",$E$8:$E$207,"有") | F5: =SUMPRODUCT(($D$8:$D$207="在籍")*((((LEFT($G$8:$G$207,2)="1級")+(LEFT($G$8:$G$207,2)="2級")+ISNUMBER(SEARCH("・特殊",$G$8:$G$207))+($G$8:$G$207="特殊"))>0))) | H5: =COUNTIF('潜水記録'!$AF$5:$AF$3004,D2)
A7: 職員番号 | B7: 氏名 | C7: 所属 | D7: 在籍 | E7: 潜水士免許 | F7: 水難救助研修 | G7: 小型船舶 | H7: 今年度 本数 | I7: 累計 本数 | J7: 累計 潜水時間(分) | K7: 最大水深(m) | L7: 最終潜水日 | M7: 最終潜水から(日)
A8: =IF('隊員マスタ'!A5="","",'隊員マスタ'!A5) | B8: =IF(A8="","",'隊員マスタ'!B5) | C8: =IF(A8="","",'隊員マスタ'!C5) | D8: =IF(A8="","",'隊員マスタ'!D5) | E8: =IF(A8="","",IF(COUNTIFS('資格研修記録'!$A$5:$A$1004,A8,'資格研修記録'!$D$5:$D$1004,"潜水士免許")>0,"有","無")) | F8: =IF(A8="","",IF(COUNTIFS('資格研修記録'!$A$5:$A$1004,A8,'資格研修記録'!$D$5:$D$1004,"水難救助研修")>0,"修了","—")) | G8: =IF(A8="","",IF((IF((COUNTIFS('資格研修記録'!$A$5:$A$1004,A8,'資格研修記録'!$D$5:$D$1004,"小型船舶1級",'資格研修記録'!$F$5:$F$1004,"")+COUNTIFS('資格研修記録'!$A$5:$A$1004,A8,'資格研修記録'!$D$5:$D$1004,"小型船舶1級",'資格研修記録'!$F$5:$F$1004,">="&TODAY()))>0,"1級",IF((COUNTIFS('資格研修記録'!$A$5:$A$1004,A8,'資格研修記録'!$D$5:$D$1004,"小型船舶2級",'資格研修記録'!$F$5:$F$1004,"")+COUNTIFS('資格研修記録'!$A$5:$A$1004,A8,'資格研修記録'!$D$5:$D$1004,"小型船舶2級",'資格研修記録'!$F$5:$F$1004,">="&TODAY()))>0,"2級",IF(COUNTIFS('資格研修記録'!$A$5:$A$1004,A8,'資格研修記録'!$D$5:$D$1004,"小型船舶1級")+COUNTIFS('資格研修記録'!$A$5:$A$1004,A8,'資格研修記録'!$D$5:$D$1004,"小型船舶2級")>0,"× 1・2級 期限切れ",""))))&(IF((COUNTIFS('資格研修記録'!$A$5:$A$1004,A8,'資格研修記録'!$D$5:$D$1004,"小型船舶特殊",'資格研修記録'!$F$5:$F$1004,"")+COUNTIFS('資格研修記録'!$A$5:$A$1004,A8,'資格研修記録'!$D$5:$D$1004,"小型船舶特殊",'資格研修記録'!$F$5:$F$1004,">="&TODAY()))>0,"特殊",IF(COUNTIFS('資格研修記録'!$A$5:$A$1004,A8,'資格研修記録'!$D$5:$D$1004,"小型船舶特殊")>0,"× 特殊 期限切れ","")))="","—",_xlfn.TEXTJOIN("・",TRUE,IF((COUNTIFS('資格研修記録'!$A$5:$A$1004,A8,'資格研修記録'!$D$5:$D$1004,"小型船舶1級",'資格研修記録'!$F$5:$F$1004,"")+COUNTIFS('資格研修記録'!$A$5:$A$1004,A8,'資格研修記録'!$D$5:$D$1004,"小型船舶1級",'資格研修記録'!$F$5:$F$1004,">="&TODAY()))>0,"1級",IF((COUNTIFS('資格研修記録'!$A$5:$A$1004,A8,'資格研修記録'!$D$5:$D$1004,"小型船舶2級",'資格研修記録'!$F$5:$F$1004,"")+COUNTIFS('資格研修記録'!$A$5:$A$1004,A8,'資格研修記録'!$D$5:$D$1004,"小型船舶2級",'資格研修記録'!$F$5:$F$1004,">="&TODAY()))>0,"2級",IF(COUNTIFS('資格研修記録'!$A$5:$A$1004,A8,'資格研修記録'!$D$5:$D$1004,"小型船舶1級")+COUNTIFS('資格研修記録'!$A$5:$A$1004,A8,'資格研修記録'!$D$5:$D$1004,"小型船舶2級")>0,"× 1・2級 期限切れ",""))),IF((COUNTIFS('資格研修記録'!$A$5:$A$1004,A8,'資格研修記録'!$D$5:$D$1004,"小型船舶特殊",'資格研修記録'!$F$5:$F$1004,"")+COUNTIFS('資格研修記録'!$A$5:$A$1004,A8,'資格研修記録'!$D$5:$D$1004,"小型船舶特殊",'資格研修記録'!$F$5:$F$1004,">="&TODAY()))>0,"特殊",IF(COUNTIFS('資格研修記録'!$A$5:$A$1004,A8,'資格研修記録'!$D$5:$D$1004,"小型船舶特殊")>0,"× 特殊 期限切れ",""))))) | H8: =IF(A8="","",COUNTIFS('潜水記録'!$B$5:$B$3004,A8,'潜水記録'!$AF$5:$AF$3004,$D$2)) | I8: =IF(A8="","",COUNTIF('潜水記録'!$B$5:$B$3004,A8)) | J8: =IF(A8="","",SUMIF('潜水記録'!$B$5:$B$3004,A8,'潜水記録'!$H$5:$H$3004)) | K8: =IF(A8="","",IF(I8=0,"",_xlfn.MAXIFS('潜水記録'!$G$5:$G$3004,'潜水記録'!$B$5:$B$3004,A8))) | L8: =IF(A8="","",IF(I8=0,"",_xlfn.MAXIFS('潜水記録'!$A$5:$A$3004,'潜水記録'!$B$5:$B$3004,A8))) | M8: =IF(L8="","",$B$2-L8)
A9: =IF('隊員マスタ'!A6="","",'隊員マスタ'!A6) | B9: =IF(A9="","",'隊員マスタ'!B6) | C9: =IF(A9="","",'隊員マスタ'!C6) | D9: =IF(A9="","",'隊員マスタ'!D6) | E9: =IF(A9="","",IF(COUNTIFS('資格研修記録'!$A$5:$A$1004,A9,'資格研修記録'!$D$5:$D$1004,"潜水士免許")>0,"有","無")) | F9: =IF(A9="","",IF(COUNTIFS('資格研修記録'!$A$5:$A$1004,A9,'資格研修記録'!$D$5:$D$1004,"水難救助研修")>0,"修了","—")) | G9: =IF(A9="","",IF((IF((COUNTIFS('資格研修記録'!$A$5:$A$1004,A9,'資格研修記録'!$D$5:$D$1004,"小型船舶1級",'資格研修記録'!$F$5:$F$1004,"")+COUNTIFS('資格研修記録'!$A$5:$A$1004,A9,'資格研修記録'!$D$5:$D$1004,"小型船舶1級",'資格研修記録'!$F$5:$F$1004,">="&TODAY()))>0,"1級",IF((COUNTIFS('資格研修記録'!$A$5:$A$1004,A9,'資格研修記録'!$D$5:$D$1004,"小型船舶2級",'資格研修記録'!$F$5:$F$1004,"")+COUNTIFS('資格研修記録'!$A$5:$A$1004,A9,'資格研修記録'!$D$5:$D$1004,"小型船舶2級",'資格研修記録'!$F$5:$F$1004,">="&TODAY()))>0,"2級",IF(COUNTIFS('資格研修記録'!$A$5:$A$1004,A9,'資格研修記録'!$D$5:$D$1004,"小型船舶1級")+COUNTIFS('資格研修記録'!$A$5:$A$1004,A9,'資格研修記録'!$D$5:$D$1004,"小型船舶2級")>0,"× 1・2級 期限切れ",""))))&(IF((COUNTIFS('資格研修記録'!$A$5:$A$1004,A9,'資格研修記録'!$D$5:$D$1004,"小型船舶特殊",'資格研修記録'!$F$5:$F$1004,"")+COUNTIFS('資格研修記録'!$A$5:$A$1004,A9,'資格研修記録'!$D$5:$D$1004,"小型船舶特殊",'資格研修記録'!$F$5:$F$1004,">="&TODAY()))>0,"特殊",IF(COUNTIFS('資格研修記録'!$A$5:$A$1004,A9,'資格研修記録'!$D$5:$D$1004,"小型船舶特殊")>0,"× 特殊 期限切れ","")))="","—",_xlfn.TEXTJOIN("・",TRUE,IF((COUNTIFS('資格研修記録'!$A$5:$A$1004,A9,'資格研修記録'!$D$5:$D$1004,"小型船舶1級",'資格研修記録'!$F$5:$F$1004,"")+COUNTIFS('資格研修記録'!$A$5:$A$1004,A9,'資格研修記録'!$D$5:$D$1004,"小型船舶1級",'資格研修記録'!$F$5:$F$1004,">="&TODAY()))>0,"1級",IF((COUNTIFS('資格研修記録'!$A$5:$A$1004,A9,'資格研修記録'!$D$5:$D$1004,"小型船舶2級",'資格研修記録'!$F$5:$F$1004,"")+COUNTIFS('資格研修記録'!$A$5:$A$1004,A9,'資格研修記録'!$D$5:$D$1004,"小型船舶2級",'資格研修記録'!$F$5:$F$1004,">="&TODAY()))>0,"2級",IF(COUNTIFS('資格研修記録'!$A$5:$A$1004,A9,'資格研修記録'!$D$5:$D$1004,"小型船舶1級")+COUNTIFS('資格研修記録'!$A$5:$A$1004,A9,'資格研修記録'!$D$5:$D$1004,"小型船舶2級")>0,"× 1・2級 期限切れ",""))),IF((COUNTIFS('資格研修記録'!$A$5:$A$1004,A9,'資格研修記録'!$D$5:$D$1004,"小型船舶特殊",'資格研修記録'!$F$5:$F$1004,"")+COUNTIFS('資格研修記録'!$A$5:$A$1004,A9,'資格研修記録'!$D$5:$D$1004,"小型船舶特殊",'資格研修記録'!$F$5:$F$1004,">="&TODAY()))>0,"特殊",IF(COUNTIFS('資格研修記録'!$A$5:$A$1004,A9,'資格研修記録'!$D$5:$D$1004,"小型船舶特殊")>0,"× 特殊 期限切れ",""))))) | H9: =IF(A9="","",COUNTIFS('潜水記録'!$B$5:$B$3004,A9,'潜水記録'!$AF$5:$AF$3004,$D$2)) | I9: =IF(A9="","",COUNTIF('潜水記録'!$B$5:$B$3004,A9)) | J9: =IF(A9="","",SUMIF('潜水記録'!$B$5:$B$3004,A9,'潜水記録'!$H$5:$H$3004)) | K9: =IF(A9="","",IF(I9=0,"",_xlfn.MAXIFS('潜水記録'!$G$5:$G$3004,'潜水記録'!$B$5:$B$3004,A9))) | L9: =IF(A9="","",IF(I9=0,"",_xlfn.MAXIFS('潜水記録'!$A$5:$A$3004,'潜水記録'!$B$5:$B$3004,A9))) | M9: =IF(L9="","",$B$2-L9)
A10: =IF('隊員マスタ'!A7="","",'隊員マスタ'!A7) | B10: =IF(A10="","",'隊員マスタ'!B7) | C10: =IF(A10="","",'隊員マスタ'!C7) | D10: =IF(A10="","",'隊員マスタ'!D7) | E10: =IF(A10="","",IF(COUNTIFS('資格研修記録'!$A$5:$A$1004,A10,'資格研修記録'!$D$5:$D$1004,"潜水士免許")>0,"有","無")) | F10: =IF(A10="","",IF(COUNTIFS('資格研修記録'!$A$5:$A$1004,A10,'資格研修記録'!$D$5:$D$1004,"水難救助研修")>0,"修了","—")) | G10: =IF(A10="","",IF((IF((COUNTIFS('資格研修記録'!$A$5:$A$1004,A10,'資格研修記録'!$D$5:$D$1004,"小型船舶1級",'資格研修記録'!$F$5:$F$1004,"")+COUNTIFS('資格研修記録'!$A$5:$A$1004,A10,'資格研修記録'!$D$5:$D$1004,"小型船舶1級",'資格研修記録'!$F$5:$F$1004,">="&TODAY()))>0,"1級",IF((COUNTIFS('資格研修記録'!$A$5:$A$1004,A10,'資格研修記録'!$D$5:$D$1004,"小型船舶2級",'資格研修記録'!$F$5:$F$1004,"")+COUNTIFS('資格研修記録'!$A$5:$A$1004,A10,'資格研修記録'!$D$5:$D$1004,"小型船舶2級",'資格研修記録'!$F$5:$F$1004,">="&TODAY()))>0,"2級",IF(COUNTIFS('資格研修記録'!$A$5:$A$1004,A10,'資格研修記録'!$D$5:$D$1004,"小型船舶1級")+COUNTIFS('資格研修記録'!$A$5:$A$1004,A10,'資格研修記録'!$D$5:$D$1004,"小型船舶2級")>0,"× 1・2級 期限切れ",""))))&(IF((COUNTIFS('資格研修記録'!$A$5:$A$1004,A10,'資格研修記録'!$D$5:$D$1004,"小型船舶特殊",'資格研修記録'!$F$5:$F$1004,"")+COUNTIFS('資格研修記録'!$A$5:$A$1004,A10,'資格研修記録'!$D$5:$D$1004,"小型船舶特殊",'資格研修記録'!$F$5:$F$1004,">="&TODAY()))>0,"特殊",IF(COUNTIFS('資格研修記録'!$A$5:$A$1004,A10,'資格研修記録'!$D$5:$D$1004,"小型船舶特殊")>0,"× 特殊 期限切れ","")))="","—",_xlfn.TEXTJOIN("・",TRUE,IF((COUNTIFS('資格研修記録'!$A$5:$A$1004,A10,'資格研修記録'!$D$5:$D$1004,"小型船舶1級",'資格研修記録'!$F$5:$F$1004,"")+COUNTIFS('資格研修記録'!$A$5:$A$1004,A10,'資格研修記録'!$D$5:$D$1004,"小型船舶1級",'資格研修記録'!$F$5:$F$1004,">="&TODAY()))>0,"1級",IF((COUNTIFS('資格研修記録'!$A$5:$A$1004,A10,'資格研修記録'!$D$5:$D$1004,"小型船舶2級",'資格研修記録'!$F$5:$F$1004,"")+COUNTIFS('資格研修記録'!$A$5:$A$1004,A10,'資格研修記録'!$D$5:$D$1004,"小型船舶2級",'資格研修記録'!$F$5:$F$1004,">="&TODAY()))>0,"2級",IF(COUNTIFS('資格研修記録'!$A$5:$A$1004,A10,'資格研修記録'!$D$5:$D$1004,"小型船舶1級")+COUNTIFS('資格研修記録'!$A$5:$A$1004,A10,'資格研修記録'!$D$5:$D$1004,"小型船舶2級")>0,"× 1・2級 期限切れ",""))),IF((COUNTIFS('資格研修記録'!$A$5:$A$1004,A10,'資格研修記録'!$D$5:$D$1004,"小型船舶特殊",'資格研修記録'!$F$5:$F$1004,"")+COUNTIFS('資格研修記録'!$A$5:$A$1004,A10,'資格研修記録'!$D$5:$D$1004,"小型船舶特殊",'資格研修記録'!$F$5:$F$1004,">="&TODAY()))>0,"特殊",IF(COUNTIFS('資格研修記録'!$A$5:$A$1004,A10,'資格研修記録'!$D$5:$D$1004,"小型船舶特殊")>0,"× 特殊 期限切れ",""))))) | H10: =IF(A10="","",COUNTIFS('潜水記録'!$B$5:$B$3004,A10,'潜水記録'!$AF$5:$AF$3004,$D$2)) | I10: =IF(A10="","",COUNTIF('潜水記録'!$B$5:$B$3004,A10)) | J10: =IF(A10="","",SUMIF('潜水記録'!$B$5:$B$3004,A10,'潜水記録'!$H$5:$H$3004)) | K10: =IF(A10="","",IF(I10=0,"",_xlfn.MAXIFS('潜水記録'!$G$5:$G$3004,'潜水記録'!$B$5:$B$3004,A10))) | L10: =IF(A10="","",IF(I10=0,"",_xlfn.MAXIFS('潜水記録'!$A$5:$A$3004,'潜水記録'!$B$5:$B$3004,A10))) | M10: =IF(L10="","",$B$2-L10)
A11: =IF('隊員マスタ'!A8="","",'隊員マスタ'!A8) | B11: =IF(A11="","",'隊員マスタ'!B8) | C11: =IF(A11="","",'隊員マスタ'!C8) | D11: =IF(A11="","",'隊員マスタ'!D8) | E11: =IF(A11="","",IF(COUNTIFS('資格研修記録'!$A$5:$A$1004,A11,'資格研修記録'!$D$5:$D$1004,"潜水士免許")>0,"有","無")) | F11: =IF(A11="","",IF(COUNTIFS('資格研修記録'!$A$5:$A$1004,A11,'資格研修記録'!$D$5:$D$1004,"水難救助研修")>0,"修了","—")) | G11: =IF(A11="","",IF((IF((COUNTIFS('資格研修記録'!$A$5:$A$1004,A11,'資格研修記録'!$D$5:$D$1004,"小型船舶1級",'資格研修記録'!$F$5:$F$1004,"")+COUNTIFS('資格研修記録'!$A$5:$A$1004,A11,'資格研修記録'!$D$5:$D$1004,"小型船舶1級",'資格研修記録'!$F$5:$F$1004,">="&TODAY()))>0,"1級",IF((COUNTIFS('資格研修記録'!$A$5:$A$1004,A11,'資格研修記録'!$D$5:$D$1004,"小型船舶2級",'資格研修記録'!$F$5:$F$1004,"")+COUNTIFS('資格研修記録'!$A$5:$A$1004,A11,'資格研修記録'!$D$5:$D$1004,"小型船舶2級",'資格研修記録'!$F$5:$F$1004,">="&TODAY()))>0,"2級",IF(COUNTIFS('資格研修記録'!$A$5:$A$1004,A11,'資格研修記録'!$D$5:$D$1004,"小型船舶1級")+COUNTIFS('資格研修記録'!$A$5:$A$1004,A11,'資格研修記録'!$D$5:$D$1004,"小型船舶2級")>0,"× 1・2級 期限切れ",""))))&(IF((COUNTIFS('資格研修記録'!$A$5:$A$1004,A11,'資格研修記録'!$D$5:$D$1004,"小型船舶特殊",'資格研修記録'!$F$5:$F$1004,"")+COUNTIFS('資格研修記録'!$A$5:$A$1004,A11,'資格研修記録'!$D$5:$D$1004,"小型船舶特殊",'資格研修記録'!$F$5:$F$1004,">="&TODAY()))>0,"特殊",IF(COUNTIFS('資格研修記録'!$A$5:$A$1004,A11,'資格研修記録'!$D$5:$D$1004,"小型船舶特殊")>0,"× 特殊 期限切れ","")))="","—",_xlfn.TEXTJOIN("・",TRUE,IF((COUNTIFS('資格研修記録'!$A$5:$A$1004,A11,'資格研修記録'!$D$5:$D$1004,"小型船舶1級",'資格研修記録'!$F$5:$F$1004,"")+COUNTIFS('資格研修記録'!$A$5:$A$1004,A11,'資格研修記録'!$D$5:$D$1004,"小型船舶1級",'資格研修記録'!$F$5:$F$1004,">="&TODAY()))>0,"1級",IF((COUNTIFS('資格研修記録'!$A$5:$A$1004,A11,'資格研修記録'!$D$5:$D$1004,"小型船舶2級",'資格研修記録'!$F$5:$F$1004,"")+COUNTIFS('資格研修記録'!$A$5:$A$1004,A11,'資格研修記録'!$D$5:$D$1004,"小型船舶2級",'資格研修記録'!$F$5:$F$1004,">="&TODAY()))>0,"2級",IF(COUNTIFS('資格研修記録'!$A$5:$A$1004,A11,'資格研修記録'!$D$5:$D$1004,"小型船舶1級")+COUNTIFS('資格研修記録'!$A$5:$A$1004,A11,'資格研修記録'!$D$5:$D$1004,"小型船舶2級")>0,"× 1・2級 期限切れ",""))),IF((COUNTIFS('資格研修記録'!$A$5:$A$1004,A11,'資格研修記録'!$D$5:$D$1004,"小型船舶特殊",'資格研修記録'!$F$5:$F$1004,"")+COUNTIFS('資格研修記録'!$A$5:$A$1004,A11,'資格研修記録'!$D$5:$D$1004,"小型船舶特殊",'資格研修記録'!$F$5:$F$1004,">="&TODAY()))>0,"特殊",IF(COUNTIFS('資格研修記録'!$A$5:$A$1004,A11,'資格研修記録'!$D$5:$D$1004,"小型船舶特殊")>0,"× 特殊 期限切れ",""))))) | H11: =IF(A11="","",COUNTIFS('潜水記録'!$B$5:$B$3004,A11,'潜水記録'!$AF$5:$AF$3004,$D$2)) | I11: =IF(A11="","",COUNTIF('潜水記録'!$B$5:$B$3004,A11)) | J11: =IF(A11="","",SUMIF('潜水記録'!$B$5:$B$3004,A11,'潜水記録'!$H$5:$H$3004)) | K11: =IF(A11="","",IF(I11=0,"",_xlfn.MAXIFS('潜水記録'!$G$5:$G$3004,'潜水記録'!$B$5:$B$3004,A11))) | L11: =IF(A11="","",IF(I11=0,"",_xlfn.MAXIFS('潜水記録'!$A$5:$A$3004,'潜水記録'!$B$5:$B$3004,A11))) | M11: =IF(L11="","",$B$2-L11)
A12: =IF('隊員マスタ'!A9="","",'隊員マスタ'!A9) | B12: =IF(A12="","",'隊員マスタ'!B9) | C12: =IF(A12="","",'隊員マスタ'!C9) | D12: =IF(A12="","",'隊員マスタ'!D9) | E12: =IF(A12="","",IF(COUNTIFS('資格研修記録'!$A$5:$A$1004,A12,'資格研修記録'!$D$5:$D$1004,"潜水士免許")>0,"有","無")) | F12: =IF(A12="","",IF(COUNTIFS('資格研修記録'!$A$5:$A$1004,A12,'資格研修記録'!$D$5:$D$1004,"水難救助研修")>0,"修了","—")) | G12: =IF(A12="","",IF((IF((COUNTIFS('資格研修記録'!$A$5:$A$1004,A12,'資格研修記録'!$D$5:$D$1004,"小型船舶1級",'資格研修記録'!$F$5:$F$1004,"")+COUNTIFS('資格研修記録'!$A$5:$A$1004,A12,'資格研修記録'!$D$5:$D$1004,"小型船舶1級",'資格研修記録'!$F$5:$F$1004,">="&TODAY()))>0,"1級",IF((COUNTIFS('資格研修記録'!$A$5:$A$1004,A12,'資格研修記録'!$D$5:$D$1004,"小型船舶2級",'資格研修記録'!$F$5:$F$1004,"")+COUNTIFS('資格研修記録'!$A$5:$A$1004,A12,'資格研修記録'!$D$5:$D$1004,"小型船舶2級",'資格研修記録'!$F$5:$F$1004,">="&TODAY()))>0,"2級",IF(COUNTIFS('資格研修記録'!$A$5:$A$1004,A12,'資格研修記録'!$D$5:$D$1004,"小型船舶1級")+COUNTIFS('資格研修記録'!$A$5:$A$1004,A12,'資格研修記録'!$D$5:$D$1004,"小型船舶2級")>0,"× 1・2級 期限切れ",""))))&(IF((COUNTIFS('資格研修記録'!$A$5:$A$1004,A12,'資格研修記録'!$D$5:$D$1004,"小型船舶特殊",'資格研修記録'!$F$5:$F$1004,"")+COUNTIFS('資格研修記録'!$A$5:$A$1004,A12,'資格研修記録'!$D$5:$D$1004,"小型船舶特殊",'資格研修記録'!$F$5:$F$1004,">="&TODAY()))>0,"特殊",IF(COUNTIFS('資格研修記録'!$A$5:$A$1004,A12,'資格研修記録'!$D$5:$D$1004,"小型船舶特殊")>0,"× 特殊 期限切れ","")))="","—",_xlfn.TEXTJOIN("・",TRUE,IF((COUNTIFS('資格研修記録'!$A$5:$A$1004,A12,'資格研修記録'!$D$5:$D$1004,"小型船舶1級",'資格研修記録'!$F$5:$F$1004,"")+COUNTIFS('資格研修記録'!$A$5:$A$1004,A12,'資格研修記録'!$D$5:$D$1004,"小型船舶1級",'資格研修記録'!$F$5:$F$1004,">="&TODAY()))>0,"1級",IF((COUNTIFS('資格研修記録'!$A$5:$A$1004,A12,'資格研修記録'!$D$5:$D$1004,"小型船舶2級",'資格研修記録'!$F$5:$F$1004,"")+COUNTIFS('資格研修記録'!$A$5:$A$1004,A12,'資格研修記録'!$D$5:$D$1004,"小型船舶2級",'資格研修記録'!$F$5:$F$1004,">="&TODAY()))>0,"2級",IF(COUNTIFS('資格研修記録'!$A$5:$A$1004,A12,'資格研修記録'!$D$5:$D$1004,"小型船舶1級")+COUNTIFS('資格研修記録'!$A$5:$A$1004,A12,'資格研修記録'!$D$5:$D$1004,"小型船舶2級")>0,"× 1・2級 期限切れ",""))),IF((COUNTIFS('資格研修記録'!$A$5:$A$1004,A12,'資格研修記録'!$D$5:$D$1004,"小型船舶特殊",'資格研修記録'!$F$5:$F$1004,"")+COUNTIFS('資格研修記録'!$A$5:$A$1004,A12,'資格研修記録'!$D$5:$D$1004,"小型船舶特殊",'資格研修記録'!$F$5:$F$1004,">="&TODAY()))>0,"特殊",IF(COUNTIFS('資格研修記録'!$A$5:$A$1004,A12,'資格研修記録'!$D$5:$D$1004,"小型船舶特殊")>0,"× 特殊 期限切れ",""))))) | H12: =IF(A12="","",COUNTIFS('潜水記録'!$B$5:$B$3004,A12,'潜水記録'!$AF$5:$AF$3004,$D$2)) | I12: =IF(A12="","",COUNTIF('潜水記録'!$B$5:$B$3004,A12)) | J12: =IF(A12="","",SUMIF('潜水記録'!$B$5:$B$3004,A12,'潜水記録'!$H$5:$H$3004)) | K12: =IF(A12="","",IF(I12=0,"",_xlfn.MAXIFS('潜水記録'!$G$5:$G$3004,'潜水記録'!$B$5:$B$3004,A12))) | L12: =IF(A12="","",IF(I12=0,"",_xlfn.MAXIFS('潜水記録'!$A$5:$A$3004,'潜水記録'!$B$5:$B$3004,A12))) | M12: =IF(L12="","",$B$2-L12)
A13: =IF('隊員マスタ'!A10="","",'隊員マスタ'!A10) | B13: =IF(A13="","",'隊員マスタ'!B10) | C13: =IF(A13="","",'隊員マスタ'!C10) | D13: =IF(A13="","",'隊員マスタ'!D10) | E13: =IF(A13="","",IF(COUNTIFS('資格研修記録'!$A$5:$A$1004,A13,'資格研修記録'!$D$5:$D$1004,"潜水士免許")>0,"有","無")) | F13: =IF(A13="","",IF(COUNTIFS('資格研修記録'!$A$5:$A$1004,A13,'資格研修記録'!$D$5:$D$1004,"水難救助研修")>0,"修了","—")) | G13: =IF(A13="","",IF((IF((COUNTIFS('資格研修記録'!$A$5:$A$1004,A13,'資格研修記録'!$D$5:$D$1004,"小型船舶1級",'資格研修記録'!$F$5:$F$1004,"")+COUNTIFS('資格研修記録'!$A$5:$A$1004,A13,'資格研修記録'!$D$5:$D$1004,"小型船舶1級",'資格研修記録'!$F$5:$F$1004,">="&TODAY()))>0,"1級",IF((COUNTIFS('資格研修記録'!$A$5:$A$1004,A13,'資格研修記録'!$D$5:$D$1004,"小型船舶2級",'資格研修記録'!$F$5:$F$1004,"")+COUNTIFS('資格研修記録'!$A$5:$A$1004,A13,'資格研修記録'!$D$5:$D$1004,"小型船舶2級",'資格研修記録'!$F$5:$F$1004,">="&TODAY()))>0,"2級",IF(COUNTIFS('資格研修記録'!$A$5:$A$1004,A13,'資格研修記録'!$D$5:$D$1004,"小型船舶1級")+COUNTIFS('資格研修記録'!$A$5:$A$1004,A13,'資格研修記録'!$D$5:$D$1004,"小型船舶2級")>0,"× 1・2級 期限切れ",""))))&(IF((COUNTIFS('資格研修記録'!$A$5:$A$1004,A13,'資格研修記録'!$D$5:$D$1004,"小型船舶特殊",'資格研修記録'!$F$5:$F$1004,"")+COUNTIFS('資格研修記録'!$A$5:$A$1004,A13,'資格研修記録'!$D$5:$D$1004,"小型船舶特殊",'資格研修記録'!$F$5:$F$1004,">="&TODAY()))>0,"特殊",IF(COUNTIFS('資格研修記録'!$A$5:$A$1004,A13,'資格研修記録'!$D$5:$D$1004,"小型船舶特殊")>0,"× 特殊 期限切れ","")))="","—",_xlfn.TEXTJOIN("・",TRUE,IF((COUNTIFS('資格研修記録'!$A$5:$A$1004,A13,'資格研修記録'!$D$5:$D$1004,"小型船舶1級",'資格研修記録'!$F$5:$F$1004,"")+COUNTIFS('資格研修記録'!$A$5:$A$1004,A13,'資格研修記録'!$D$5:$D$1004,"小型船舶1級",'資格研修記録'!$F$5:$F$1004,">="&TODAY()))>0,"1級",IF((COUNTIFS('資格研修記録'!$A$5:$A$1004,A13,'資格研修記録'!$D$5:$D$1004,"小型船舶2級",'資格研修記録'!$F$5:$F$1004,"")+COUNTIFS('資格研修記録'!$A$5:$A$1004,A13,'資格研修記録'!$D$5:$D$1004,"小型船舶2級",'資格研修記録'!$F$5:$F$1004,">="&TODAY()))>0,"2級",IF(COUNTIFS('資格研修記録'!$A$5:$A$1004,A13,'資格研修記録'!$D$5:$D$1004,"小型船舶1級")+COUNTIFS('資格研修記録'!$A$5:$A$1004,A13,'資格研修記録'!$D$5:$D$1004,"小型船舶2級")>0,"× 1・2級 期限切れ",""))),IF((COUNTIFS('資格研修記録'!$A$5:$A$1004,A13,'資格研修記録'!$D$5:$D$1004,"小型船舶特殊",'資格研修記録'!$F$5:$F$1004,"")+COUNTIFS('資格研修記録'!$A$5:$A$1004,A13,'資格研修記録'!$D$5:$D$1004,"小型船舶特殊",'資格研修記録'!$F$5:$F$1004,">="&TODAY()))>0,"特殊",IF(COUNTIFS('資格研修記録'!$A$5:$A$1004,A13,'資格研修記録'!$D$5:$D$1004,"小型船舶特殊")>0,"× 特殊 期限切れ",""))))) | H13: =IF(A13="","",COUNTIFS('潜水記録'!$B$5:$B$3004,A13,'潜水記録'!$AF$5:$AF$3004,$D$2)) | I13: =IF(A13="","",COUNTIF('潜水記録'!$B$5:$B$3004,A13)) | J13: =IF(A13="","",SUMIF('潜水記録'!$B$5:$B$3004,A13,'潜水記録'!$H$5:$H$3004)) | K13: =IF(A13="","",IF(I13=0,"",_xlfn.MAXIFS('潜水記録'!$G$5:$G$3004,'潜水記録'!$B$5:$B$3004,A13))) | L13: =IF(A13="","",IF(I13=0,"",_xlfn.MAXIFS('潜水記録'!$A$5:$A$3004,'潜水記録'!$B$5:$B$3004,A13))) | M13: =IF(L13="","",$B$2-L13)
A14: =IF('隊員マスタ'!A11="","",'隊員マスタ'!A11) | B14: =IF(A14="","",'隊員マスタ'!B11) | C14: =IF(A14="","",'隊員マスタ'!C11) | D14: =IF(A14="","",'隊員マスタ'!D11) | E14: =IF(A14="","",IF(COUNTIFS('資格研修記録'!$A$5:$A$1004,A14,'資格研修記録'!$D$5:$D$1004,"潜水士免許")>0,"有","無")) | F14: =IF(A14="","",IF(COUNTIFS('資格研修記録'!$A$5:$A$1004,A14,'資格研修記録'!$D$5:$D$1004,"水難救助研修")>0,"修了","—")) | G14: =IF(A14="","",IF((IF((COUNTIFS('資格研修記録'!$A$5:$A$1004,A14,'資格研修記録'!$D$5:$D$1004,"小型船舶1級",'資格研修記録'!$F$5:$F$1004,"")+COUNTIFS('資格研修記録'!$A$5:$A$1004,A14,'資格研修記録'!$D$5:$D$1004,"小型船舶1級",'資格研修記録'!$F$5:$F$1004,">="&TODAY()))>0,"1級",IF((COUNTIFS('資格研修記録'!$A$5:$A$1004,A14,'資格研修記録'!$D$5:$D$1004,"小型船舶2級",'資格研修記録'!$F$5:$F$1004,"")+COUNTIFS('資格研修記録'!$A$5:$A$1004,A14,'資格研修記録'!$D$5:$D$1004,"小型船舶2級",'資格研修記録'!$F$5:$F$1004,">="&TODAY()))>0,"2級",IF(COUNTIFS('資格研修記録'!$A$5:$A$1004,A14,'資格研修記録'!$D$5:$D$1004,"小型船舶1級")+COUNTIFS('資格研修記録'!$A$5:$A$1004,A14,'資格研修記録'!$D$5:$D$1004,"小型船舶2級")>0,"× 1・2級 期限切れ",""))))&(IF((COUNTIFS('資格研修記録'!$A$5:$A$1004,A14,'資格研修記録'!$D$5:$D$1004,"小型船舶特殊",'資格研修記録'!$F$5:$F$1004,"")+COUNTIFS('資格研修記録'!$A$5:$A$1004,A14,'資格研修記録'!$D$5:$D$1004,"小型船舶特殊",'資格研修記録'!$F$5:$F$1004,">="&TODAY()))>0,"特殊",IF(COUNTIFS('資格研修記録'!$A$5:$A$1004,A14,'資格研修記録'!$D$5:$D$1004,"小型船舶特殊")>0,"× 特殊 期限切れ","")))="","—",_xlfn.TEXTJOIN("・",TRUE,IF((COUNTIFS('資格研修記録'!$A$5:$A$1004,A14,'資格研修記録'!$D$5:$D$1004,"小型船舶1級",'資格研修記録'!$F$5:$F$1004,"")+COUNTIFS('資格研修記録'!$A$5:$A$1004,A14,'資格研修記録'!$D$5:$D$1004,"小型船舶1級",'資格研修記録'!$F$5:$F$1004,">="&TODAY()))>0,"1級",IF((COUNTIFS('資格研修記録'!$A$5:$A$1004,A14,'資格研修記録'!$D$5:$D$1004,"小型船舶2級",'資格研修記録'!$F$5:$F$1004,"")+COUNTIFS('資格研修記録'!$A$5:$A$1004,A14,'資格研修記録'!$D$5:$D$1004,"小型船舶2級",'資格研修記録'!$F$5:$F$1004,">="&TODAY()))>0,"2級",IF(COUNTIFS('資格研修記録'!$A$5:$A$1004,A14,'資格研修記録'!$D$5:$D$1004,"小型船舶1級")+COUNTIFS('資格研修記録'!$A$5:$A$1004,A14,'資格研修記録'!$D$5:$D$1004,"小型船舶2級")>0,"× 1・2級 期限切れ",""))),IF((COUNTIFS('資格研修記録'!$A$5:$A$1004,A14,'資格研修記録'!$D$5:$D$1004,"小型船舶特殊",'資格研修記録'!$F$5:$F$1004,"")+COUNTIFS('資格研修記録'!$A$5:$A$1004,A14,'資格研修記録'!$D$5:$D$1004,"小型船舶特殊",'資格研修記録'!$F$5:$F$1004,">="&TODAY()))>0,"特殊",IF(COUNTIFS('資格研修記録'!$A$5:$A$1004,A14,'資格研修記録'!$D$5:$D$1004,"小型船舶特殊")>0,"× 特殊 期限切れ",""))))) | H14: =IF(A14="","",COUNTIFS('潜水記録'!$B$5:$B$3004,A14,'潜水記録'!$AF$5:$AF$3004,$D$2)) | I14: =IF(A14="","",COUNTIF('潜水記録'!$B$5:$B$3004,A14)) | J14: =IF(A14="","",SUMIF('潜水記録'!$B$5:$B$3004,A14,'潜水記録'!$H$5:$H$3004)) | K14: =IF(A14="","",IF(I14=0,"",_xlfn.MAXIFS('潜水記録'!$G$5:$G$3004,'潜水記録'!$B$5:$B$3004,A14))) | L14: =IF(A14="","",IF(I14=0,"",_xlfn.MAXIFS('潜水記録'!$A$5:$A$3004,'潜水記録'!$B$5:$B$3004,A14))) | M14: =IF(L14="","",$B$2-L14)
A15: =IF('隊員マスタ'!A12="","",'隊員マスタ'!A12) | B15: =IF(A15="","",'隊員マスタ'!B12) | C15: =IF(A15="","",'隊員マスタ'!C12) | D15: =IF(A15="","",'隊員マスタ'!D12) | E15: =IF(A15="","",IF(COUNTIFS('資格研修記録'!$A$5:$A$1004,A15,'資格研修記録'!$D$5:$D$1004,"潜水士免許")>0,"有","無")) | F15: =IF(A15="","",IF(COUNTIFS('資格研修記録'!$A$5:$A$1004,A15,'資格研修記録'!$D$5:$D$1004,"水難救助研修")>0,"修了","—")) | G15: =IF(A15="","",IF((IF((COUNTIFS('資格研修記録'!$A$5:$A$1004,A15,'資格研修記録'!$D$5:$D$1004,"小型船舶1級",'資格研修記録'!$F$5:$F$1004,"")+COUNTIFS('資格研修記録'!$A$5:$A$1004,A15,'資格研修記録'!$D$5:$D$1004,"小型船舶1級",'資格研修記録'!$F$5:$F$1004,">="&TODAY()))>0,"1級",IF((COUNTIFS('資格研修記録'!$A$5:$A$1004,A15,'資格研修記録'!$D$5:$D$1004,"小型船舶2級",'資格研修記録'!$F$5:$F$1004,"")+COUNTIFS('資格研修記録'!$A$5:$A$1004,A15,'資格研修記録'!$D$5:$D$1004,"小型船舶2級",'資格研修記録'!$F$5:$F$1004,">="&TODAY()))>0,"2級",IF(COUNTIFS('資格研修記録'!$A$5:$A$1004,A15,'資格研修記録'!$D$5:$D$1004,"小型船舶1級")+COUNTIFS('資格研修記録'!$A$5:$A$1004,A15,'資格研修記録'!$D$5:$D$1004,"小型船舶2級")>0,"× 1・2級 期限切れ",""))))&(IF((COUNTIFS('資格研修記録'!$A$5:$A$1004,A15,'資格研修記録'!$D$5:$D$1004,"小型船舶特殊",'資格研修記録'!$F$5:$F$1004,"")+COUNTIFS('資格研修記録'!$A$5:$A$1004,A15,'資格研修記録'!$D$5:$D$1004,"小型船舶特殊",'資格研修記録'!$F$5:$F$1004,">="&TODAY()))>0,"特殊",IF(COUNTIFS('資格研修記録'!$A$5:$A$1004,A15,'資格研修記録'!$D$5:$D$1004,"小型船舶特殊")>0,"× 特殊 期限切れ","")))="","—",_xlfn.TEXTJOIN("・",TRUE,IF((COUNTIFS('資格研修記録'!$A$5:$A$1004,A15,'資格研修記録'!$D$5:$D$1004,"小型船舶1級",'資格研修記録'!$F$5:$F$1004,"")+COUNTIFS('資格研修記録'!$A$5:$A$1004,A15,'資格研修記録'!$D$5:$D$1004,"小型船舶1級",'資格研修記録'!$F$5:$F$1004,">="&TODAY()))>0,"1級",IF((COUNTIFS('資格研修記録'!$A$5:$A$1004,A15,'資格研修記録'!$D$5:$D$1004,"小型船舶2級",'資格研修記録'!$F$5:$F$1004,"")+COUNTIFS('資格研修記録'!$A$5:$A$1004,A15,'資格研修記録'!$D$5:$D$1004,"小型船舶2級",'資格研修記録'!$F$5:$F$1004,">="&TODAY()))>0,"2級",IF(COUNTIFS('資格研修記録'!$A$5:$A$1004,A15,'資格研修記録'!$D$5:$D$1004,"小型船舶1級")+COUNTIFS('資格研修記録'!$A$5:$A$1004,A15,'資格研修記録'!$D$5:$D$1004,"小型船舶2級")>0,"× 1・2級 期限切れ",""))),IF((COUNTIFS('資格研修記録'!$A$5:$A$1004,A15,'資格研修記録'!$D$5:$D$1004,"小型船舶特殊",'資格研修記録'!$F$5:$F$1004,"")+COUNTIFS('資格研修記録'!$A$5:$A$1004,A15,'資格研修記録'!$D$5:$D$1004,"小型船舶特殊",'資格研修記録'!$F$5:$F$1004,">="&TODAY()))>0,"特殊",IF(COUNTIFS('資格研修記録'!$A$5:$A$1004,A15,'資格研修記録'!$D$5:$D$1004,"小型船舶特殊")>0,"× 特殊 期限切れ",""))))) | H15: =IF(A15="","",COUNTIFS('潜水記録'!$B$5:$B$3004,A15,'潜水記録'!$AF$5:$AF$3004,$D$2)) | I15: =IF(A15="","",COUNTIF('潜水記録'!$B$5:$B$3004,A15)) | J15: =IF(A15="","",SUMIF('潜水記録'!$B$5:$B$3004,A15,'潜水記録'!$H$5:$H$3004)) | K15: =IF(A15="","",IF(I15=0,"",_xlfn.MAXIFS('潜水記録'!$G$5:$G$3004,'潜水記録'!$B$5:$B$3004,A15))) | L15: =IF(A15="","",IF(I15=0,"",_xlfn.MAXIFS('潜水記録'!$A$5:$A$3004,'潜水記録'!$B$5:$B$3004,A15))) | M15: =IF(L15="","",$B$2-L15)
A16: =IF('隊員マスタ'!A13="","",'隊員マスタ'!A13) | B16: =IF(A16="","",'隊員マスタ'!B13) | C16: =IF(A16="","",'隊員マスタ'!C13) | D16: =IF(A16="","",'隊員マスタ'!D13) | E16: =IF(A16="","",IF(COUNTIFS('資格研修記録'!$A$5:$A$1004,A16,'資格研修記録'!$D$5:$D$1004,"潜水士免許")>0,"有","無")) | F16: =IF(A16="","",IF(COUNTIFS('資格研修記録'!$A$5:$A$1004,A16,'資格研修記録'!$D$5:$D$1004,"水難救助研修")>0,"修了","—")) | G16: =IF(A16="","",IF((IF((COUNTIFS('資格研修記録'!$A$5:$A$1004,A16,'資格研修記録'!$D$5:$D$1004,"小型船舶1級",'資格研修記録'!$F$5:$F$1004,"")+COUNTIFS('資格研修記録'!$A$5:$A$1004,A16,'資格研修記録'!$D$5:$D$1004,"小型船舶1級",'資格研修記録'!$F$5:$F$1004,">="&TODAY()))>0,"1級",IF((COUNTIFS('資格研修記録'!$A$5:$A$1004,A16,'資格研修記録'!$D$5:$D$1004,"小型船舶2級",'資格研修記録'!$F$5:$F$1004,"")+COUNTIFS('資格研修記録'!$A$5:$A$1004,A16,'資格研修記録'!$D$5:$D$1004,"小型船舶2級",'資格研修記録'!$F$5:$F$1004,">="&TODAY()))>0,"2級",IF(COUNTIFS('資格研修記録'!$A$5:$A$1004,A16,'資格研修記録'!$D$5:$D$1004,"小型船舶1級")+COUNTIFS('資格研修記録'!$A$5:$A$1004,A16,'資格研修記録'!$D$5:$D$1004,"小型船舶2級")>0,"× 1・2級 期限切れ",""))))&(IF((COUNTIFS('資格研修記録'!$A$5:$A$1004,A16,'資格研修記録'!$D$5:$D$1004,"小型船舶特殊",'資格研修記録'!$F$5:$F$1004,"")+COUNTIFS('資格研修記録'!$A$5:$A$1004,A16,'資格研修記録'!$D$5:$D$1004,"小型船舶特殊",'資格研修記録'!$F$5:$F$1004,">="&TODAY()))>0,"特殊",IF(COUNTIFS('資格研修記録'!$A$5:$A$1004,A16,'資格研修記録'!$D$5:$D$1004,"小型船舶特殊")>0,"× 特殊 期限切れ","")))="","—",_xlfn.TEXTJOIN("・",TRUE,IF((COUNTIFS('資格研修記録'!$A$5:$A$1004,A16,'資格研修記録'!$D$5:$D$1004,"小型船舶1級",'資格研修記録'!$F$5:$F$1004,"")+COUNTIFS('資格研修記録'!$A$5:$A$1004,A16,'資格研修記録'!$D$5:$D$1004,"小型船舶1級",'資格研修記録'!$F$5:$F$1004,">="&TODAY()))>0,"1級",IF((COUNTIFS('資格研修記録'!$A$5:$A$1004,A16,'資格研修記録'!$D$5:$D$1004,"小型船舶2級",'資格研修記録'!$F$5:$F$1004,"")+COUNTIFS('資格研修記録'!$A$5:$A$1004,A16,'資格研修記録'!$D$5:$D$1004,"小型船舶2級",'資格研修記録'!$F$5:$F$1004,">="&TODAY()))>0,"2級",IF(COUNTIFS('資格研修記録'!$A$5:$A$1004,A16,'資格研修記録'!$D$5:$D$1004,"小型船舶1級")+COUNTIFS('資格研修記録'!$A$5:$A$1004,A16,'資格研修記録'!$D$5:$D$1004,"小型船舶2級")>0,"× 1・2級 期限切れ",""))),IF((COUNTIFS('資格研修記録'!$A$5:$A$1004,A16,'資格研修記録'!$D$5:$D$1004,"小型船舶特殊",'資格研修記録'!$F$5:$F$1004,"")+COUNTIFS('資格研修記録'!$A$5:$A$1004,A16,'資格研修記録'!$D$5:$D$1004,"小型船舶特殊",'資格研修記録'!$F$5:$F$1004,">="&TODAY()))>0,"特殊",IF(COUNTIFS('資格研修記録'!$A$5:$A$1004,A16,'資格研修記録'!$D$5:$D$1004,"小型船舶特殊")>0,"× 特殊 期限切れ",""))))) | H16: =IF(A16="","",COUNTIFS('潜水記録'!$B$5:$B$3004,A16,'潜水記録'!$AF$5:$AF$3004,$D$2)) | I16: =IF(A16="","",COUNTIF('潜水記録'!$B$5:$B$3004,A16)) | J16: =IF(A16="","",SUMIF('潜水記録'!$B$5:$B$3004,A16,'潜水記録'!$H$5:$H$3004)) | K16: =IF(A16="","",IF(I16=0,"",_xlfn.MAXIFS('潜水記録'!$G$5:$G$3004,'潜水記録'!$B$5:$B$3004,A16))) | L16: =IF(A16="","",IF(I16=0,"",_xlfn.MAXIFS('潜水記録'!$A$5:$A$3004,'潜水記録'!$B$5:$B$3004,A16))) | M16: =IF(L16="","",$B$2-L16)
A17: =IF('隊員マスタ'!A14="","",'隊員マスタ'!A14) | B17: =IF(A17="","",'隊員マスタ'!B14) | C17: =IF(A17="","",'隊員マスタ'!C14) | D17: =IF(A17="","",'隊員マスタ'!D14) | E17: =IF(A17="","",IF(COUNTIFS('資格研修記録'!$A$5:$A$1004,A17,'資格研修記録'!$D$5:$D$1004,"潜水士免許")>0,"有","無")) | F17: =IF(A17="","",IF(COUNTIFS('資格研修記録'!$A$5:$A$1004,A17,'資格研修記録'!$D$5:$D$1004,"水難救助研修")>0,"修了","—")) | G17: =IF(A17="","",IF((IF((COUNTIFS('資格研修記録'!$A$5:$A$1004,A17,'資格研修記録'!$D$5:$D$1004,"小型船舶1級",'資格研修記録'!$F$5:$F$1004,"")+COUNTIFS('資格研修記録'!$A$5:$A$1004,A17,'資格研修記録'!$D$5:$D$1004,"小型船舶1級",'資格研修記録'!$F$5:$F$1004,">="&TODAY()))>0,"1級",IF((COUNTIFS('資格研修記録'!$A$5:$A$1004,A17,'資格研修記録'!$D$5:$D$1004,"小型船舶2級",'資格研修記録'!$F$5:$F$1004,"")+COUNTIFS('資格研修記録'!$A$5:$A$1004,A17,'資格研修記録'!$D$5:$D$1004,"小型船舶2級",'資格研修記録'!$F$5:$F$1004,">="&TODAY()))>0,"2級",IF(COUNTIFS('資格研修記録'!$A$5:$A$1004,A17,'資格研修記録'!$D$5:$D$1004,"小型船舶1級")+COUNTIFS('資格研修記録'!$A$5:$A$1004,A17,'資格研修記録'!$D$5:$D$1004,"小型船舶2級")>0,"× 1・2級 期限切れ",""))))&(IF((COUNTIFS('資格研修記録'!$A$5:$A$1004,A17,'資格研修記録'!$D$5:$D$1004,"小型船舶特殊",'資格研修記録'!$F$5:$F$1004,"")+COUNTIFS('資格研修記録'!$A$5:$A$1004,A17,'資格研修記録'!$D$5:$D$1004,"小型船舶特殊",'資格研修記録'!$F$5:$F$1004,">="&TODAY()))>0,"特殊",IF(COUNTIFS('資格研修記録'!$A$5:$A$1004,A17,'資格研修記録'!$D$5:$D$1004,"小型船舶特殊")>0,"× 特殊 期限切れ","")))="","—",_xlfn.TEXTJOIN("・",TRUE,IF((COUNTIFS('資格研修記録'!$A$5:$A$1004,A17,'資格研修記録'!$D$5:$D$1004,"小型船舶1級",'資格研修記録'!$F$5:$F$1004,"")+COUNTIFS('資格研修記録'!$A$5:$A$1004,A17,'資格研修記録'!$D$5:$D$1004,"小型船舶1級",'資格研修記録'!$F$5:$F$1004,">="&TODAY()))>0,"1級",IF((COUNTIFS('資格研修記録'!$A$5:$A$1004,A17,'資格研修記録'!$D$5:$D$1004,"小型船舶2級",'資格研修記録'!$F$5:$F$1004,"")+COUNTIFS('資格研修記録'!$A$5:$A$1004,A17,'資格研修記録'!$D$5:$D$1004,"小型船舶2級",'資格研修記録'!$F$5:$F$1004,">="&TODAY()))>0,"2級",IF(COUNTIFS('資格研修記録'!$A$5:$A$1004,A17,'資格研修記録'!$D$5:$D$1004,"小型船舶1級")+COUNTIFS('資格研修記録'!$A$5:$A$1004,A17,'資格研修記録'!$D$5:$D$1004,"小型船舶2級")>0,"× 1・2級 期限切れ",""))),IF((COUNTIFS('資格研修記録'!$A$5:$A$1004,A17,'資格研修記録'!$D$5:$D$1004,"小型船舶特殊",'資格研修記録'!$F$5:$F$1004,"")+COUNTIFS('資格研修記録'!$A$5:$A$1004,A17,'資格研修記録'!$D$5:$D$1004,"小型船舶特殊",'資格研修記録'!$F$5:$F$1004,">="&TODAY()))>0,"特殊",IF(COUNTIFS('資格研修記録'!$A$5:$A$1004,A17,'資格研修記録'!$D$5:$D$1004,"小型船舶特殊")>0,"× 特殊 期限切れ",""))))) | H17: =IF(A17="","",COUNTIFS('潜水記録'!$B$5:$B$3004,A17,'潜水記録'!$AF$5:$AF$3004,$D$2)) | I17: =IF(A17="","",COUNTIF('潜水記録'!$B$5:$B$3004,A17)) | J17: =IF(A17="","",SUMIF('潜水記録'!$B$5:$B$3004,A17,'潜水記録'!$H$5:$H$3004)) | K17: =IF(A17="","",IF(I17=0,"",_xlfn.MAXIFS('潜水記録'!$G$5:$G$3004,'潜水記録'!$B$5:$B$3004,A17))) | L17: =IF(A17="","",IF(I17=0,"",_xlfn.MAXIFS('潜水記録'!$A$5:$A$3004,'潜水記録'!$B$5:$B$3004,A17))) | M17: =IF(L17="","",$B$2-L17)
A18: =IF('隊員マスタ'!A15="","",'隊員マスタ'!A15) | B18: =IF(A18="","",'隊員マスタ'!B15) | C18: =IF(A18="","",'隊員マスタ'!C15) | D18: =IF(A18="","",'隊員マスタ'!D15) | E18: =IF(A18="","",IF(COUNTIFS('資格研修記録'!$A$5:$A$1004,A18,'資格研修記録'!$D$5:$D$1004,"潜水士免許")>0,"有","無")) | F18: =IF(A18="","",IF(COUNTIFS('資格研修記録'!$A$5:$A$1004,A18,'資格研修記録'!$D$5:$D$1004,"水難救助研修")>0,"修了","—")) | G18: =IF(A18="","",IF((IF((COUNTIFS('資格研修記録'!$A$5:$A$1004,A18,'資格研修記録'!$D$5:$D$1004,"小型船舶1級",'資格研修記録'!$F$5:$F$1004,"")+COUNTIFS('資格研修記録'!$A$5:$A$1004,A18,'資格研修記録'!$D$5:$D$1004,"小型船舶1級",'資格研修記録'!$F$5:$F$1004,">="&TODAY()))>0,"1級",IF((COUNTIFS('資格研修記録'!$A$5:$A$1004,A18,'資格研修記録'!$D$5:$D$1004,"小型船舶2級",'資格研修記録'!$F$5:$F$1004,"")+COUNTIFS('資格研修記録'!$A$5:$A$1004,A18,'資格研修記録'!$D$5:$D$1004,"小型船舶2級",'資格研修記録'!$F$5:$F$1004,">="&TODAY()))>0,"2級",IF(COUNTIFS('資格研修記録'!$A$5:$A$1004,A18,'資格研修記録'!$D$5:$D$1004,"小型船舶1級")+COUNTIFS('資格研修記録'!$A$5:$A$1004,A18,'資格研修記録'!$D$5:$D$1004,"小型船舶2級")>0,"× 1・2級 期限切れ",""))))&(IF((COUNTIFS('資格研修記録'!$A$5:$A$1004,A18,'資格研修記録'!$D$5:$D$1004,"小型船舶特殊",'資格研修記録'!$F$5:$F$1004,"")+COUNTIFS('資格研修記録'!$A$5:$A$1004,A18,'資格研修記録'!$D$5:$D$1004,"小型船舶特殊",'資格研修記録'!$F$5:$F$1004,">="&TODAY()))>0,"特殊",IF(COUNTIFS('資格研修記録'!$A$5:$A$1004,A18,'資格研修記録'!$D$5:$D$1004,"小型船舶特殊")>0,"× 特殊 期限切れ","")))="","—",_xlfn.TEXTJOIN("・",TRUE,IF((COUNTIFS('資格研修記録'!$A$5:$A$1004,A18,'資格研修記録'!$D$5:$D$1004,"小型船舶1級",'資格研修記録'!$F$5:$F$1004,"")+COUNTIFS('資格研修記録'!$A$5:$A$1004,A18,'資格研修記録'!$D$5:$D$1004,"小型船舶1級",'資格研修記録'!$F$5:$F$1004,">="&TODAY()))>0,"1級",IF((COUNTIFS('資格研修記録'!$A$5:$A$1004,A18,'資格研修記録'!$D$5:$D$1004,"小型船舶2級",'資格研修記録'!$F$5:$F$1004,"")+COUNTIFS('資格研修記録'!$A$5:$A$1004,A18,'資格研修記録'!$D$5:$D$1004,"小型船舶2級",'資格研修記録'!$F$5:$F$1004,">="&TODAY()))>0,"2級",IF(COUNTIFS('資格研修記録'!$A$5:$A$1004,A18,'資格研修記録'!$D$5:$D$1004,"小型船舶1級")+COUNTIFS('資格研修記録'!$A$5:$A$1004,A18,'資格研修記録'!$D$5:$D$1004,"小型船舶2級")>0,"× 1・2級 期限切れ",""))),IF((COUNTIFS('資格研修記録'!$A$5:$A$1004,A18,'資格研修記録'!$D$5:$D$1004,"小型船舶特殊",'資格研修記録'!$F$5:$F$1004,"")+COUNTIFS('資格研修記録'!$A$5:$A$1004,A18,'資格研修記録'!$D$5:$D$1004,"小型船舶特殊",'資格研修記録'!$F$5:$F$1004,">="&TODAY()))>0,"特殊",IF(COUNTIFS('資格研修記録'!$A$5:$A$1004,A18,'資格研修記録'!$D$5:$D$1004,"小型船舶特殊")>0,"× 特殊 期限切れ",""))))) | H18: =IF(A18="","",COUNTIFS('潜水記録'!$B$5:$B$3004,A18,'潜水記録'!$AF$5:$AF$3004,$D$2)) | I18: =IF(A18="","",COUNTIF('潜水記録'!$B$5:$B$3004,A18)) | J18: =IF(A18="","",SUMIF('潜水記録'!$B$5:$B$3004,A18,'潜水記録'!$H$5:$H$3004)) | K18: =IF(A18="","",IF(I18=0,"",_xlfn.MAXIFS('潜水記録'!$G$5:$G$3004,'潜水記録'!$B$5:$B$3004,A18))) | L18: =IF(A18="","",IF(I18=0,"",_xlfn.MAXIFS('潜水記録'!$A$5:$A$3004,'潜水記録'!$B$5:$B$3004,A18))) | M18: =IF(L18="","",$B$2-L18)
A19: =IF('隊員マスタ'!A16="","",'隊員マスタ'!A16) | B19: =IF(A19="","",'隊員マスタ'!B16) | C19: =IF(A19="","",'隊員マスタ'!C16) | D19: =IF(A19="","",'隊員マスタ'!D16) | E19: =IF(A19="","",IF(COUNTIFS('資格研修記録'!$A$5:$A$1004,A19,'資格研修記録'!$D$5:$D$1004,"潜水士免許")>0,"有","無")) | F19: =IF(A19="","",IF(COUNTIFS('資格研修記録'!$A$5:$A$1004,A19,'資格研修記録'!$D$5:$D$1004,"水難救助研修")>0,"修了","—")) | G19: =IF(A19="","",IF((IF((COUNTIFS('資格研修記録'!$A$5:$A$1004,A19,'資格研修記録'!$D$5:$D$1004,"小型船舶1級",'資格研修記録'!$F$5:$F$1004,"")+COUNTIFS('資格研修記録'!$A$5:$A$1004,A19,'資格研修記録'!$D$5:$D$1004,"小型船舶1級",'資格研修記録'!$F$5:$F$1004,">="&TODAY()))>0,"1級",IF((COUNTIFS('資格研修記録'!$A$5:$A$1004,A19,'資格研修記録'!$D$5:$D$1004,"小型船舶2級",'資格研修記録'!$F$5:$F$1004,"")+COUNTIFS('資格研修記録'!$A$5:$A$1004,A19,'資格研修記録'!$D$5:$D$1004,"小型船舶2級",'資格研修記録'!$F$5:$F$1004,">="&TODAY()))>0,"2級",IF(COUNTIFS('資格研修記録'!$A$5:$A$1004,A19,'資格研修記録'!$D$5:$D$1004,"小型船舶1級")+COUNTIFS('資格研修記録'!$A$5:$A$1004,A19,'資格研修記録'!$D$5:$D$1004,"小型船舶2級")>0,"× 1・2級 期限切れ",""))))&(IF((COUNTIFS('資格研修記録'!$A$5:$A$1004,A19,'資格研修記録'!$D$5:$D$1004,"小型船舶特殊",'資格研修記録'!$F$5:$F$1004,"")+COUNTIFS('資格研修記録'!$A$5:$A$1004,A19,'資格研修記録'!$D$5:$D$1004,"小型船舶特殊",'資格研修記録'!$F$5:$F$1004,">="&TODAY()))>0,"特殊",IF(COUNTIFS('資格研修記録'!$A$5:$A$1004,A19,'資格研修記録'!$D$5:$D$1004,"小型船舶特殊")>0,"× 特殊 期限切れ","")))="","—",_xlfn.TEXTJOIN("・",TRUE,IF((COUNTIFS('資格研修記録'!$A$5:$A$1004,A19,'資格研修記録'!$D$5:$D$1004,"小型船舶1級",'資格研修記録'!$F$5:$F$1004,"")+COUNTIFS('資格研修記録'!$A$5:$A$1004,A19,'資格研修記録'!$D$5:$D$1004,"小型船舶1級",'資格研修記録'!$F$5:$F$1004,">="&TODAY()))>0,"1級",IF((COUNTIFS('資格研修記録'!$A$5:$A$1004,A19,'資格研修記録'!$D$5:$D$1004,"小型船舶2級",'資格研修記録'!$F$5:$F$1004,"")+COUNTIFS('資格研修記録'!$A$5:$A$1004,A19,'資格研修記録'!$D$5:$D$1004,"小型船舶2級",'資格研修記録'!$F$5:$F$1004,">="&TODAY()))>0,"2級",IF(COUNTIFS('資格研修記録'!$A$5:$A$1004,A19,'資格研修記録'!$D$5:$D$1004,"小型船舶1級")+COUNTIFS('資格研修記録'!$A$5:$A$1004,A19,'資格研修記録'!$D$5:$D$1004,"小型船舶2級")>0,"× 1・2級 期限切れ",""))),IF((COUNTIFS('資格研修記録'!$A$5:$A$1004,A19,'資格研修記録'!$D$5:$D$1004,"小型船舶特殊",'資格研修記録'!$F$5:$F$1004,"")+COUNTIFS('資格研修記録'!$A$5:$A$1004,A19,'資格研修記録'!$D$5:$D$1004,"小型船舶特殊",'資格研修記録'!$F$5:$F$1004,">="&TODAY()))>0,"特殊",IF(COUNTIFS('資格研修記録'!$A$5:$A$1004,A19,'資格研修記録'!$D$5:$D$1004,"小型船舶特殊")>0,"× 特殊 期限切れ",""))))) | H19: =IF(A19="","",COUNTIFS('潜水記録'!$B$5:$B$3004,A19,'潜水記録'!$AF$5:$AF$3004,$D$2)) | I19: =IF(A19="","",COUNTIF('潜水記録'!$B$5:$B$3004,A19)) | J19: =IF(A19="","",SUMIF('潜水記録'!$B$5:$B$3004,A19,'潜水記録'!$H$5:$H$3004)) | K19: =IF(A19="","",IF(I19=0,"",_xlfn.MAXIFS('潜水記録'!$G$5:$G$3004,'潜水記録'!$B$5:$B$3004,A19))) | L19: =IF(A19="","",IF(I19=0,"",_xlfn.MAXIFS('潜水記録'!$A$5:$A$3004,'潜水記録'!$B$5:$B$3004,A19))) | M19: =IF(L19="","",$B$2-L19)
... A207: =IF('隊員マスタ'!A204="","",'隊員マスタ'!A204) | B207: =IF(A207="","",'隊員マスタ'!B204) | C207: =IF(A207="","",'隊員マスタ'!C204) | D207: =IF(A207="","",'隊員マスタ'!D204) | E207: =IF(A207="","",IF(COUNTIFS('資格研修記録'!$A$5:$A$1004,A207,'資格研修記録'!$D$5:$D$1004,"潜水士免許")>0,"有","無")) | F207: =IF(A207="","",IF(COUNTIFS('資格研修記録'!$A$5:$A$1004,A207,'資格研修記録'!$D$5:$D$1004,"水難救助研修")>0,"修了","—")) | G207: =IF(A207="","",IF((IF((COUNTIFS('資格研修記録'!$A$5:$A$1004,A207,'資格研修記録'!$D$5:$D$1004,"小型船舶1級",'資格研修記録'!$F$5:$F$1004,"")+COUNTIFS('資格研修記録'!$A$5:$A$1004,A207,'資格研修記録'!$D$5:$D$1004,"小型船舶1級",'資格研修記録'!$F$5:$F$1004,">="&TODAY()))>0,"1級",IF((COUNTIFS('資格研修記録'!$A$5:$A$1004,A207,'資格研修記録'!$D$5:$D$1004,"小型船舶2級",'資格研修記録'!$F$5:$F$1004,"")+COUNTIFS('資格研修記録'!$A$5:$A$1004,A207,'資格研修記録'!$D$5:$D$1004,"小型船舶2級",'資格研修記録'!$F$5:$F$1004,">="&TODAY()))>0,"2級",IF(COUNTIFS('資格研修記録'!$A$5:$A$1004,A207,'資格研修記録'!$D$5:$D$1004,"小型船舶1級")+COUNTIFS('資格研修記録'!$A$5:$A$1004,A207,'資格研修記録'!$D$5:$D$1004,"小型船舶2級")>0,"× 1・2級 期限切れ",""))))&(IF((COUNTIFS('資格研修記録'!$A$5:$A$1004,A207,'資格研修記録'!$D$5:$D$1004,"小型船舶特殊",'資格研修記録'!$F$5:$F$1004,"")+COUNTIFS('資格研修記録'!$A$5:$A$1004,A207,'資格研修記録'!$D$5:$D$1004,"小型船舶特殊",'資格研修記録'!$F$5:$F$1004,">="&TODAY()))>0,"特殊",IF(COUNTIFS('資格研修記録'!$A$5:$A$1004,A207,'資格研修記録'!$D$5:$D$1004,"小型船舶特殊")>0,"× 特殊 期限切れ","")))="","—",_xlfn.TEXTJOIN("・",TRUE,IF((COUNTIFS('資格研修記録'!$A$5:$A$1004,A207,'資格研修記録'!$D$5:$D$1004,"小型船舶1級",'資格研修記録'!$F$5:$F$1004,"")+COUNTIFS('資格研修記録'!$A$5:$A$1004,A207,'資格研修記録'!$D$5:$D$1004,"小型船舶1級",'資格研修記録'!$F$5:$F$1004,">="&TODAY()))>0,"1級",IF((COUNTIFS('資格研修記録'!$A$5:$A$1004,A207,'資格研修記録'!$D$5:$D$1004,"小型船舶2級",'資格研修記録'!$F$5:$F$1004,"")+COUNTIFS('資格研修記録'!$A$5:$A$1004,A207,'資格研修記録'!$D$5:$D$1004,"小型船舶2級",'資格研修記録'!$F$5:$F$1004,">="&TODAY()))>0,"2級",IF(COUNTIFS('資格研修記録'!$A$5:$A$1004,A207,'資格研修記録'!$D$5:$D$1004,"小型船舶1級")+COUNTIFS('資格研修記録'!$A$5:$A$1004,A207,'資格研修記録'!$D$5:$D$1004,"小型船舶2級")>0,"× 1・2級 期限切れ",""))),IF((COUNTIFS('資格研修記録'!$A$5:$A$1004,A207,'資格研修記録'!$D$5:$D$1004,"小型船舶特殊",'資格研修記録'!$F$5:$F$1004,"")+COUNTIFS('資格研修記録'!$A$5:$A$1004,A207,'資格研修記録'!$D$5:$D$1004,"小型船舶特殊",'資格研修記録'!$F$5:$F$1004,">="&TODAY()))>0,"特殊",IF(COUNTIFS('資格研修記録'!$A$5:$A$1004,A207,'資格研修記録'!$D$5:$D$1004,"小型船舶特殊")>0,"× 特殊 期限切れ",""))))) | H207: =IF(A207="","",COUNTIFS('潜水記録'!$B$5:$B$3004,A207,'潜水記録'!$AF$5:$AF$3004,$D$2)) | I207: =IF(A207="","",COUNTIF('潜水記録'!$B$5:$B$3004,A207)) | J207: =IF(A207="","",SUMIF('潜水記録'!$B$5:$B$3004,A207,'潜水記録'!$H$5:$H$3004)) | K207: =IF(A207="","",IF(I207=0,"",_xlfn.MAXIFS('潜水記録'!$G$5:$G$3004,'潜水記録'!$B$5:$B$3004,A207))) | L207: =IF(A207="","",IF(I207=0,"",_xlfn.MAXIFS('潜水記録'!$A$5:$A$3004,'潜水記録'!$B$5:$B$3004,A207))) | M207: =IF(L207="","",$B$2-L207)

Sheet 資格一覧
A1: 資格・研修一覧
A2: ○＝有効、× 期限切れ＝有効期限を過ぎた記録のみ、—＝記録なし、1級に含む＝1級が有効なので2級は不要。列見出しは「選択肢」の資格・研修名（先頭8件）。
A4: 職員番号 | B4: 氏名 | C4: 所属 | D4: 在籍 | E4: =IF('選択肢'!D5="","",'選択肢'!D5) | F4: =IF('選択肢'!D6="","",'選択肢'!D6) | G4: =IF('選択肢'!D7="","",'選択肢'!D7) | H4: =IF('選択肢'!D8="","",'選択肢'!D8) | I4: =IF('選択肢'!D9="","",'選択肢'!D9) | J4: =IF('選択肢'!D10="","",'選択肢'!D10) | K4: =IF('選択肢'!D11="","",'選択肢'!D11) | L4: =IF('選択肢'!D12="","",'選択肢'!D12)
A5: =IF('隊員マスタ'!A5="","",'隊員マスタ'!A5) | B5: =IF(A5="","",'隊員マスタ'!B5) | C5: =IF(A5="","",'隊員マスタ'!C5) | D5: =IF(A5="","",'隊員マスタ'!D5) | E5: =IF(OR($A5="",E$4=""),"",IF(AND(E$4="小型船舶2級",(COUNTIFS('資格研修記録'!$A$5:$A$1004,$A5,'資格研修記録'!$D$5:$D$1004,"小型船舶1級",'資格研修記録'!$F$5:$F$1004,"")+COUNTIFS('資格研修記録'!$A$5:$A$1004,$A5,'資格研修記録'!$D$5:$D$1004,"小型船舶1級",'資格研修記録'!$F$5:$F$1004,">="&TODAY()))>0),"1級に含む",IF(COUNTIFS('資格研修記録'!$A$5:$A$1004,$A5,'資格研修記録'!$D$5:$D$1004,E$4)=0,"—",IF(COUNTIFS('資格研修記録'!$A$5:$A$1004,$A5,'資格研修記録'!$D$5:$D$1004,E$4,'資格研修記録'!$F$5:$F$1004,"")+COUNTIFS('資格研修記録'!$A$5:$A$1004,$A5,'資格研修記録'!$D$5:$D$1004,E$4,'資格研修記録'!$F$5:$F$1004,">="&TODAY())>0,"○","× 期限切れ")))) | F5: =IF(OR($A5="",F$4=""),"",IF(AND(F$4="小型船舶2級",(COUNTIFS('資格研修記録'!$A$5:$A$1004,$A5,'資格研修記録'!$D$5:$D$1004,"小型船舶1級",'資格研修記録'!$F$5:$F$1004,"")+COUNTIFS('資格研修記録'!$A$5:$A$1004,$A5,'資格研修記録'!$D$5:$D$1004,"小型船舶1級",'資格研修記録'!$F$5:$F$1004,">="&TODAY()))>0),"1級に含む",IF(COUNTIFS('資格研修記録'!$A$5:$A$1004,$A5,'資格研修記録'!$D$5:$D$1004,F$4)=0,"—",IF(COUNTIFS('資格研修記録'!$A$5:$A$1004,$A5,'資格研修記録'!$D$5:$D$1004,F$4,'資格研修記録'!$F$5:$F$1004,"")+COUNTIFS('資格研修記録'!$A$5:$A$1004,$A5,'資格研修記録'!$D$5:$D$1004,F$4,'資格研修記録'!$F$5:$F$1004,">="&TODAY())>0,"○","× 期限切れ")))) | G5: =IF(OR($A5="",G$4=""),"",IF(AND(G$4="小型船舶2級",(COUNTIFS('資格研修記録'!$A$5:$A$1004,$A5,'資格研修記録'!$D$5:$D$1004,"小型船舶1級",'資格研修記録'!$F$5:$F$1004,"")+COUNTIFS('資格研修記録'!$A$5:$A$1004,$A5,'資格研修記録'!$D$5:$D$1004,"小型船舶1級",'資格研修記録'!$F$5:$F$1004,">="&TODAY()))>0),"1級に含む",IF(COUNTIFS('資格研修記録'!$A$5:$A$1004,$A5,'資格研修記録'!$D$5:$D$1004,G$4)=0,"—",IF(COUNTIFS('資格研修記録'!$A$5:$A$1004,$A5,'資格研修記録'!$D$5:$D$1004,G$4,'資格研修記録'!$F$5:$F$1004,"")+COUNTIFS('資格研修記録'!$A$5:$A$1004,$A5,'資格研修記録'!$D$5:$D$1004,G$4,'資格研修記録'!$F$5:$F$1004,">="&TODAY())>0,"○","× 期限切れ")))) | H5: =IF(OR($A5="",H$4=""),"",IF(AND(H$4="小型船舶2級",(COUNTIFS('資格研修記録'!$A$5:$A$1004,$A5,'資格研修記録'!$D$5:$D$1004,"小型船舶1級",'資格研修記録'!$F$5:$F$1004,"")+COUNTIFS('資格研修記録'!$A$5:$A$1004,$A5,'資格研修記録'!$D$5:$D$1004,"小型船舶1級",'資格研修記録'!$F$5:$F$1004,">="&TODAY()))>0),"1級に含む",IF(COUNTIFS('資格研修記録'!$A$5:$A$1004,$A5,'資格研修記録'!$D$5:$D$1004,H$4)=0,"—",IF(COUNTIFS('資格研修記録'!$A$5:$A$1004,$A5,'資格研修記録'!$D$5:$D$1004,H$4,'資格研修記録'!$F$5:$F$1004,"")+COUNTIFS('資格研修記録'!$A$5:$A$1004,$A5,'資格研修記録'!$D$5:$D$1004,H$4,'資格研修記録'!$F$5:$F$1004,">="&TODAY())>0,"○","× 期限切れ")))) | I5: =IF(OR($A5="",I$4=""),"",IF(AND(I$4="小型船舶2級",(COUNTIFS('資格研修記録'!$A$5:$A$1004,$A5,'資格研修記録'!$D$5:$D$1004,"小型船舶1級",'資格研修記録'!$F$5:$F$1004,"")+COUNTIFS('資格研修記録'!$A$5:$A$1004,$A5,'資格研修記録'!$D$5:$D$1004,"小型船舶1級",'資格研修記録'!$F$5:$F$1004,">="&TODAY()))>0),"1級に含む",IF(COUNTIFS('資格研修記録'!$A$5:$A$1004,$A5,'資格研修記録'!$D$5:$D$1004,I$4)=0,"—",IF(COUNTIFS('資格研修記録'!$A$5:$A$1004,$A5,'資格研修記録'!$D$5:$D$1004,I$4,'資格研修記録'!$F$5:$F$1004,"")+COUNTIFS('資格研修記録'!$A$5:$A$1004,$A5,'資格研修記録'!$D$5:$D$1004,I$4,'資格研修記録'!$F$5:$F$1004,">="&TODAY())>0,"○","× 期限切れ")))) | J5: =IF(OR($A5="",J$4=""),"",IF(AND(J$4="小型船舶2級",(COUNTIFS('資格研修記録'!$A$5:$A$1004,$A5,'資格研修記録'!$D$5:$D$1004,"小型船舶1級",'資格研修記録'!$F$5:$F$1004,"")+COUNTIFS('資格研修記録'!$A$5:$A$1004,$A5,'資格研修記録'!$D$5:$D$1004,"小型船舶1級",'資格研修記録'!$F$5:$F$1004,">="&TODAY()))>0),"1級に含む",IF(COUNTIFS('資格研修記録'!$A$5:$A$1004,$A5,'資格研修記録'!$D$5:$D$1004,J$4)=0,"—",IF(COUNTIFS('資格研修記録'!$A$5:$A$1004,$A5,'資格研修記録'!$D$5:$D$1004,J$4,'資格研修記録'!$F$5:$F$1004,"")+COUNTIFS('資格研修記録'!$A$5:$A$1004,$A5,'資格研修記録'!$D$5:$D$1004,J$4,'資格研修記録'!$F$5:$F$1004,">="&TODAY())>0,"○","× 期限切れ")))) | K5: =IF(OR($A5="",K$4=""),"",IF(AND(K$4="小型船舶2級",(COUNTIFS('資格研修記録'!$A$5:$A$1004,$A5,'資格研修記録'!$D$5:$D$1004,"小型船舶1級",'資格研修記録'!$F$5:$F$1004,"")+COUNTIFS('資格研修記録'!$A$5:$A$1004,$A5,'資格研修記録'!$D$5:$D$1004,"小型船舶1級",'資格研修記録'!$F$5:$F$1004,">="&TODAY()))>0),"1級に含む",IF(COUNTIFS('資格研修記録'!$A$5:$A$1004,$A5,'資格研修記録'!$D$5:$D$1004,K$4)=0,"—",IF(COUNTIFS('資格研修記録'!$A$5:$A$1004,$A5,'資格研修記録'!$D$5:$D$1004,K$4,'資格研修記録'!$F$5:$F$1004,"")+COUNTIFS('資格研修記録'!$A$5:$A$1004,$A5,'資格研修記録'!$D$5:$D$1004,K$4,'資格研修記録'!$F$5:$F$1004,">="&TODAY())>0,"○","× 期限切れ")))) | L5: =IF(OR($A5="",L$4=""),"",IF(AND(L$4="小型船舶2級",(COUNTIFS('資格研修記録'!$A$5:$A$1004,$A5,'資格研修記録'!$D$5:$D$1004,"小型船舶1級",'資格研修記録'!$F$5:$F$1004,"")+COUNTIFS('資格研修記録'!$A$5:$A$1004,$A5,'資格研修記録'!$D$5:$D$1004,"小型船舶1級",'資格研修記録'!$F$5:$F$1004,">="&TODAY()))>0),"1級に含む",IF(COUNTIFS('資格研修記録'!$A$5:$A$1004,$A5,'資格研修記録'!$D$5:$D$1004,L$4)=0,"—",IF(COUNTIFS('資格研修記録'!$A$5:$A$1004,$A5,'資格研修記録'!$D$5:$D$1004,L$4,'資格研修記録'!$F$5:$F$1004,"")+COUNTIFS('資格研修記録'!$A$5:$A$1004,$A5,'資格研修記録'!$D$5:$D$1004,L$4,'資格研修記録'!$F$5:$F$1004,">="&TODAY())>0,"○","× 期限切れ"))))
A6: =IF('隊員マスタ'!A6="","",'隊員マスタ'!A6) | B6: =IF(A6="","",'隊員マスタ'!B6) | C6: =IF(A6="","",'隊員マスタ'!C6) | D6: =IF(A6="","",'隊員マスタ'!D6) | E6: =IF(OR($A6="",E$4=""),"",IF(AND(E$4="小型船舶2級",(COUNTIFS('資格研修記録'!$A$5:$A$1004,$A6,'資格研修記録'!$D$5:$D$1004,"小型船舶1級",'資格研修記録'!$F$5:$F$1004,"")+COUNTIFS('資格研修記録'!$A$5:$A$1004,$A6,'資格研修記録'!$D$5:$D$1004,"小型船舶1級",'資格研修記録'!$F$5:$F$1004,">="&TODAY()))>0),"1級に含む",IF(COUNTIFS('資格研修記録'!$A$5:$A$1004,$A6,'資格研修記録'!$D$5:$D$1004,E$4)=0,"—",IF(COUNTIFS('資格研修記録'!$A$5:$A$1004,$A6,'資格研修記録'!$D$5:$D$1004,E$4,'資格研修記録'!$F$5:$F$1004,"")+COUNTIFS('資格研修記録'!$A$5:$A$1004,$A6,'資格研修記録'!$D$5:$D$1004,E$4,'資格研修記録'!$F$5:$F$1004,">="&TODAY())>0,"○","× 期限切れ")))) | F6: =IF(OR($A6="",F$4=""),"",IF(AND(F$4="小型船舶2級",(COUNTIFS('資格研修記録'!$A$5:$A$1004,$A6,'資格研修記録'!$D$5:$D$1004,"小型船舶1級",'資格研修記録'!$F$5:$F$1004,"")+COUNTIFS('資格研修記録'!$A$5:$A$1004,$A6,'資格研修記録'!$D$5:$D$1004,"小型船舶1級",'資格研修記録'!$F$5:$F$1004,">="&TODAY()))>0),"1級に含む",IF(COUNTIFS('資格研修記録'!$A$5:$A$1004,$A6,'資格研修記録'!$D$5:$D$1004,F$4)=0,"—",IF(COUNTIFS('資格研修記録'!$A$5:$A$1004,$A6,'資格研修記録'!$D$5:$D$1004,F$4,'資格研修記録'!$F$5:$F$1004,"")+COUNTIFS('資格研修記録'!$A$5:$A$1004,$A6,'資格研修記録'!$D$5:$D$1004,F$4,'資格研修記録'!$F$5:$F$1004,">="&TODAY())>0,"○","× 期限切れ")))) | G6: =IF(OR($A6="",G$4=""),"",IF(AND(G$4="小型船舶2級",(COUNTIFS('資格研修記録'!$A$5:$A$1004,$A6,'資格研修記録'!$D$5:$D$1004,"小型船舶1級",'資格研修記録'!$F$5:$F$1004,"")+COUNTIFS('資格研修記録'!$A$5:$A$1004,$A6,'資格研修記録'!$D$5:$D$1004,"小型船舶1級",'資格研修記録'!$F$5:$F$1004,">="&TODAY()))>0),"1級に含む",IF(COUNTIFS('資格研修記録'!$A$5:$A$1004,$A6,'資格研修記録'!$D$5:$D$1004,G$4)=0,"—",IF(COUNTIFS('資格研修記録'!$A$5:$A$1004,$A6,'資格研修記録'!$D$5:$D$1004,G$4,'資格研修記録'!$F$5:$F$1004,"")+COUNTIFS('資格研修記録'!$A$5:$A$1004,$A6,'資格研修記録'!$D$5:$D$1004,G$4,'資格研修記録'!$F$5:$F$1004,">="&TODAY())>0,"○","× 期限切れ")))) | H6: =IF(OR($A6="",H$4=""),"",IF(AND(H$4="小型船舶2級",(COUNTIFS('資格研修記録'!$A$5:$A$1004,$A6,'資格研修記録'!$D$5:$D$1004,"小型船舶1級",'資格研修記録'!$F$5:$F$1004,"")+COUNTIFS('資格研修記録'!$A$5:$A$1004,$A6,'資格研修記録'!$D$5:$D$1004,"小型船舶1級",'資格研修記録'!$F$5:$F$1004,">="&TODAY()))>0),"1級に含む",IF(COUNTIFS('資格研修記録'!$A$5:$A$1004,$A6,'資格研修記録'!$D$5:$D$1004,H$4)=0,"—",IF(COUNTIFS('資格研修記録'!$A$5:$A$1004,$A6,'資格研修記録'!$D$5:$D$1004,H$4,'資格研修記録'!$F$5:$F$1004,"")+COUNTIFS('資格研修記録'!$A$5:$A$1004,$A6,'資格研修記録'!$D$5:$D$1004,H$4,'資格研修記録'!$F$5:$F$1004,">="&TODAY())>0,"○","× 期限切れ")))) | I6: =IF(OR($A6="",I$4=""),"",IF(AND(I$4="小型船舶2級",(COUNTIFS('資格研修記録'!$A$5:$A$1004,$A6,'資格研修記録'!$D$5:$D$1004,"小型船舶1級",'資格研修記録'!$F$5:$F$1004,"")+COUNTIFS('資格研修記録'!$A$5:$A$1004,$A6,'資格研修記録'!$D$5:$D$1004,"小型船舶1級",'資格研修記録'!$F$5:$F$1004,">="&TODAY()))>0),"1級に含む",IF(COUNTIFS('資格研修記録'!$A$5:$A$1004,$A6,'資格研修記録'!$D$5:$D$1004,I$4)=0,"—",IF(COUNTIFS('資格研修記録'!$A$5:$A$1004,$A6,'資格研修記録'!$D$5:$D$1004,I$4,'資格研修記録'!$F$5:$F$1004,"")+COUNTIFS('資格研修記録'!$A$5:$A$1004,$A6,'資格研修記録'!$D$5:$D$1004,I$4,'資格研修記録'!$F$5:$F$1004,">="&TODAY())>0,"○","× 期限切れ")))) | J6: =IF(OR($A6="",J$4=""),"",IF(AND(J$4="小型船舶2級",(COUNTIFS('資格研修記録'!$A$5:$A$1004,$A6,'資格研修記録'!$D$5:$D$1004,"小型船舶1級",'資格研修記録'!$F$5:$F$1004,"")+COUNTIFS('資格研修記録'!$A$5:$A$1004,$A6,'資格研修記録'!$D$5:$D$1004,"小型船舶1級",'資格研修記録'!$F$5:$F$1004,">="&TODAY()))>0),"1級に含む",IF(COUNTIFS('資格研修記録'!$A$5:$A$1004,$A6,'資格研修記録'!$D$5:$D$1004,J$4)=0,"—",IF(COUNTIFS('資格研修記録'!$A$5:$A$1004,$A6,'資格研修記録'!$D$5:$D$1004,J$4,'資格研修記録'!$F$5:$F$1004,"")+COUNTIFS('資格研修記録'!$A$5:$A$1004,$A6,'資格研修記録'!$D$5:$D$1004,J$4,'資格研修記録'!$F$5:$F$1004,">="&TODAY())>0,"○","× 期限切れ")))) | K6: =IF(OR($A6="",K$4=""),"",IF(AND(K$4="小型船舶2級",(COUNTIFS('資格研修記録'!$A$5:$A$1004,$A6,'資格研修記録'!$D$5:$D$1004,"小型船舶1級",'資格研修記録'!$F$5:$F$1004,"")+COUNTIFS('資格研修記録'!$A$5:$A$1004,$A6,'資格研修記録'!$D$5:$D$1004,"小型船舶1級",'資格研修記録'!$F$5:$F$1004,">="&TODAY()))>0),"1級に含む",IF(COUNTIFS('資格研修記録'!$A$5:$A$1004,$A6,'資格研修記録'!$D$5:$D$1004,K$4)=0,"—",IF(COUNTIFS('資格研修記録'!$A$5:$A$1004,$A6,'資格研修記録'!$D$5:$D$1004,K$4,'資格研修記録'!$F$5:$F$1004,"")+COUNTIFS('資格研修記録'!$A$5:$A$1004,$A6,'資格研修記録'!$D$5:$D$1004,K$4,'資格研修記録'!$F$5:$F$1004,">="&TODAY())>0,"○","× 期限切れ")))) | L6: =IF(OR($A6="",L$4=""),"",IF(AND(L$4="小型船舶2級",(COUNTIFS('資格研修記録'!$A$5:$A$1004,$A6,'資格研修記録'!$D$5:$D$1004,"小型船舶1級",'資格研修記録'!$F$5:$F$1004,"")+COUNTIFS('資格研修記録'!$A$5:$A$1004,$A6,'資格研修記録'!$D$5:$D$1004,"小型船舶1級",'資格研修記録'!$F$5:$F$1004,">="&TODAY()))>0),"1級に含む",IF(COUNTIFS('資格研修記録'!$A$5:$A$1004,$A6,'資格研修記録'!$D$5:$D$1004,L$4)=0,"—",IF(COUNTIFS('資格研修記録'!$A$5:$A$1004,$A6,'資格研修記録'!$D$5:$D$1004,L$4,'資格研修記録'!$F$5:$F$1004,"")+COUNTIFS('資格研修記録'!$A$5:$A$1004,$A6,'資格研修記録'!$D$5:$D$1004,L$4,'資格研修記録'!$F$5:$F$1004,">="&TODAY())>0,"○","× 期限切れ"))))
A7: =IF('隊員マスタ'!A7="","",'隊員マスタ'!A7) | B7: =IF(A7="","",'隊員マスタ'!B7) | C7: =IF(A7="","",'隊員マスタ'!C7) | D7: =IF(A7="","",'隊員マスタ'!D7) | E7: =IF(OR($A7="",E$4=""),"",IF(AND(E$4="小型船舶2級",(COUNTIFS('資格研修記録'!$A$5:$A$1004,$A7,'資格研修記録'!$D$5:$D$1004,"小型船舶1級",'資格研修記録'!$F$5:$F$1004,"")+COUNTIFS('資格研修記録'!$A$5:$A$1004,$A7,'資格研修記録'!$D$5:$D$1004,"小型船舶1級",'資格研修記録'!$F$5:$F$1004,">="&TODAY()))>0),"1級に含む",IF(COUNTIFS('資格研修記録'!$A$5:$A$1004,$A7,'資格研修記録'!$D$5:$D$1004,E$4)=0,"—",IF(COUNTIFS('資格研修記録'!$A$5:$A$1004,$A7,'資格研修記録'!$D$5:$D$1004,E$4,'資格研修記録'!$F$5:$F$1004,"")+COUNTIFS('資格研修記録'!$A$5:$A$1004,$A7,'資格研修記録'!$D$5:$D$1004,E$4,'資格研修記録'!$F$5:$F$1004,">="&TODAY())>0,"○","× 期限切れ")))) | F7: =IF(OR($A7="",F$4=""),"",IF(AND(F$4="小型船舶2級",(COUNTIFS('資格研修記録'!$A$5:$A$1004,$A7,'資格研修記録'!$D$5:$D$1004,"小型船舶1級",'資格研修記録'!$F$5:$F$1004,"")+COUNTIFS('資格研修記録'!$A$5:$A$1004,$A7,'資格研修記録'!$D$5:$D$1004,"小型船舶1級",'資格研修記録'!$F$5:$F$1004,">="&TODAY()))>0),"1級に含む",IF(COUNTIFS('資格研修記録'!$A$5:$A$1004,$A7,'資格研修記録'!$D$5:$D$1004,F$4)=0,"—",IF(COUNTIFS('資格研修記録'!$A$5:$A$1004,$A7,'資格研修記録'!$D$5:$D$1004,F$4,'資格研修記録'!$F$5:$F$1004,"")+COUNTIFS('資格研修記録'!$A$5:$A$1004,$A7,'資格研修記録'!$D$5:$D$1004,F$4,'資格研修記録'!$F$5:$F$1004,">="&TODAY())>0,"○","× 期限切れ")))) | G7: =IF(OR($A7="",G$4=""),"",IF(AND(G$4="小型船舶2級",(COUNTIFS('資格研修記録'!$A$5:$A$1004,$A7,'資格研修記録'!$D$5:$D$1004,"小型船舶1級",'資格研修記録'!$F$5:$F$1004,"")+COUNTIFS('資格研修記録'!$A$5:$A$1004,$A7,'資格研修記録'!$D$5:$D$1004,"小型船舶1級",'資格研修記録'!$F$5:$F$1004,">="&TODAY()))>0),"1級に含む",IF(COUNTIFS('資格研修記録'!$A$5:$A$1004,$A7,'資格研修記録'!$D$5:$D$1004,G$4)=0,"—",IF(COUNTIFS('資格研修記録'!$A$5:$A$1004,$A7,'資格研修記録'!$D$5:$D$1004,G$4,'資格研修記録'!$F$5:$F$1004,"")+COUNTIFS('資格研修記録'!$A$5:$A$1004,$A7,'資格研修記録'!$D$5:$D$1004,G$4,'資格研修記録'!$F$5:$F$1004,">="&TODAY())>0,"○","× 期限切れ")))) | H7: =IF(OR($A7="",H$4=""),"",IF(AND(H$4="小型船舶2級",(COUNTIFS('資格研修記録'!$A$5:$A$1004,$A7,'資格研修記録'!$D$5:$D$1004,"小型船舶1級",'資格研修記録'!$F$5:$F$1004,"")+COUNTIFS('資格研修記録'!$A$5:$A$1004,$A7,'資格研修記録'!$D$5:$D$1004,"小型船舶1級",'資格研修記録'!$F$5:$F$1004,">="&TODAY()))>0),"1級に含む",IF(COUNTIFS('資格研修記録'!$A$5:$A$1004,$A7,'資格研修記録'!$D$5:$D$1004,H$4)=0,"—",IF(COUNTIFS('資格研修記録'!$A$5:$A$1004,$A7,'資格研修記録'!$D$5:$D$1004,H$4,'資格研修記録'!$F$5:$F$1004,"")+COUNTIFS('資格研修記録'!$A$5:$A$1004,$A7,'資格研修記録'!$D$5:$D$1004,H$4,'資格研修記録'!$F$5:$F$1004,">="&TODAY())>0,"○","× 期限切れ")))) | I7: =IF(OR($A7="",I$4=""),"",IF(AND(I$4="小型船舶2級",(COUNTIFS('資格研修記録'!$A$5:$A$1004,$A7,'資格研修記録'!$D$5:$D$1004,"小型船舶1級",'資格研修記録'!$F$5:$F$1004,"")+COUNTIFS('資格研修記録'!$A$5:$A$1004,$A7,'資格研修記録'!$D$5:$D$1004,"小型船舶1級",'資格研修記録'!$F$5:$F$1004,">="&TODAY()))>0),"1級に含む",IF(COUNTIFS('資格研修記録'!$A$5:$A$1004,$A7,'資格研修記録'!$D$5:$D$1004,I$4)=0,"—",IF(COUNTIFS('資格研修記録'!$A$5:$A$1004,$A7,'資格研修記録'!$D$5:$D$1004,I$4,'資格研修記録'!$F$5:$F$1004,"")+COUNTIFS('資格研修記録'!$A$5:$A$1004,$A7,'資格研修記録'!$D$5:$D$1004,I$4,'資格研修記録'!$F$5:$F$1004,">="&TODAY())>0,"○","× 期限切れ")))) | J7: =IF(OR($A7="",J$4=""),"",IF(AND(J$4="小型船舶2級",(COUNTIFS('資格研修記録'!$A$5:$A$1004,$A7,'資格研修記録'!$D$5:$D$1004,"小型船舶1級",'資格研修記録'!$F$5:$F$1004,"")+COUNTIFS('資格研修記録'!$A$5:$A$1004,$A7,'資格研修記録'!$D$5:$D$1004,"小型船舶1級",'資格研修記録'!$F$5:$F$1004,">="&TODAY()))>0),"1級に含む",IF(COUNTIFS('資格研修記録'!$A$5:$A$1004,$A7,'資格研修記録'!$D$5:$D$1004,J$4)=0,"—",IF(COUNTIFS('資格研修記録'!$A$5:$A$1004,$A7,'資格研修記録'!$D$5:$D$1004,J$4,'資格研修記録'!$F$5:$F$1004,"")+COUNTIFS('資格研修記録'!$A$5:$A$1004,$A7,'資格研修記録'!$D$5:$D$1004,J$4,'資格研修記録'!$F$5:$F$1004,">="&TODAY())>0,"○","× 期限切れ")))) | K7: =IF(OR($A7="",K$4=""),"",IF(AND(K$4="小型船舶2級",(COUNTIFS('資格研修記録'!$A$5:$A$1004,$A7,'資格研修記録'!$D$5:$D$1004,"小型船舶1級",'資格研修記録'!$F$5:$F$1004,"")+COUNTIFS('資格研修記録'!$A$5:$A$1004,$A7,'資格研修記録'!$D$5:$D$1004,"小型船舶1級",'資格研修記録'!$F$5:$F$1004,">="&TODAY()))>0),"1級に含む",IF(COUNTIFS('資格研修記録'!$A$5:$A$1004,$A7,'資格研修記録'!$D$5:$D$1004,K$4)=0,"—",IF(COUNTIFS('資格研修記録'!$A$5:$A$1004,$A7,'資格研修記録'!$D$5:$D$1004,K$4,'資格研修記録'!$F$5:$F$1004,"")+COUNTIFS('資格研修記録'!$A$5:$A$1004,$A7,'資格研修記録'!$D$5:$D$1004,K$4,'資格研修記録'!$F$5:$F$1004,">="&TODAY())>0,"○","× 期限切れ")))) | L7: =IF(OR($A7="",L$4=""),"",IF(AND(L$4="小型船舶2級",(COUNTIFS('資格研修記録'!$A$5:$A$1004,$A7,'資格研修記録'!$D$5:$D$1004,"小型船舶1級",'資格研修記録'!$F$5:$F$1004,"")+COUNTIFS('資格研修記録'!$A$5:$A$1004,$A7,'資格研修記録'!$D$5:$D$1004,"小型船舶1級",'資格研修記録'!$F$5:$F$1004,">="&TODAY()))>0),"1級に含む",IF(COUNTIFS('資格研修記録'!$A$5:$A$1004,$A7,'資格研修記録'!$D$5:$D$1004,L$4)=0,"—",IF(COUNTIFS('資格研修記録'!$A$5:$A$1004,$A7,'資格研修記録'!$D$5:$D$1004,L$4,'資格研修記録'!$F$5:$F$1004,"")+COUNTIFS('資格研修記録'!$A$5:$A$1004,$A7,'資格研修記録'!$D$5:$D$1004,L$4,'資格研修記録'!$F$5:$F$1004,">="&TODAY())>0,"○","× 期限切れ"))))
A8: =IF('隊員マスタ'!A8="","",'隊員マスタ'!A8) | B8: =IF(A8="","",'隊員マスタ'!B8) | C8: =IF(A8="","",'隊員マスタ'!C8) | D8: =IF(A8="","",'隊員マスタ'!D8) | E8: =IF(OR($A8="",E$4=""),"",IF(AND(E$4="小型船舶2級",(COUNTIFS('資格研修記録'!$A$5:$A$1004,$A8,'資格研修記録'!$D$5:$D$1004,"小型船舶1級",'資格研修記録'!$F$5:$F$1004,"")+COUNTIFS('資格研修記録'!$A$5:$A$1004,$A8,'資格研修記録'!$D$5:$D$1004,"小型船舶1級",'資格研修記録'!$F$5:$F$1004,">="&TODAY()))>0),"1級に含む",IF(COUNTIFS('資格研修記録'!$A$5:$A$1004,$A8,'資格研修記録'!$D$5:$D$1004,E$4)=0,"—",IF(COUNTIFS('資格研修記録'!$A$5:$A$1004,$A8,'資格研修記録'!$D$5:$D$1004,E$4,'資格研修記録'!$F$5:$F$1004,"")+COUNTIFS('資格研修記録'!$A$5:$A$1004,$A8,'資格研修記録'!$D$5:$D$1004,E$4,'資格研修記録'!$F$5:$F$1004,">="&TODAY())>0,"○","× 期限切れ")))) | F8: =IF(OR($A8="",F$4=""),"",IF(AND(F$4="小型船舶2級",(COUNTIFS('資格研修記録'!$A$5:$A$1004,$A8,'資格研修記録'!$D$5:$D$1004,"小型船舶1級",'資格研修記録'!$F$5:$F$1004,"")+COUNTIFS('資格研修記録'!$A$5:$A$1004,$A8,'資格研修記録'!$D$5:$D$1004,"小型船舶1級",'資格研修記録'!$F$5:$F$1004,">="&TODAY()))>0),"1級に含む",IF(COUNTIFS('資格研修記録'!$A$5:$A$1004,$A8,'資格研修記録'!$D$5:$D$1004,F$4)=0,"—",IF(COUNTIFS('資格研修記録'!$A$5:$A$1004,$A8,'資格研修記録'!$D$5:$D$1004,F$4,'資格研修記録'!$F$5:$F$1004,"")+COUNTIFS('資格研修記録'!$A$5:$A$1004,$A8,'資格研修記録'!$D$5:$D$1004,F$4,'資格研修記録'!$F$5:$F$1004,">="&TODAY())>0,"○","× 期限切れ")))) | G8: =IF(OR($A8="",G$4=""),"",IF(AND(G$4="小型船舶2級",(COUNTIFS('資格研修記録'!$A$5:$A$1004,$A8,'資格研修記録'!$D$5:$D$1004,"小型船舶1級",'資格研修記録'!$F$5:$F$1004,"")+COUNTIFS('資格研修記録'!$A$5:$A$1004,$A8,'資格研修記録'!$D$5:$D$1004,"小型船舶1級",'資格研修記録'!$F$5:$F$1004,">="&TODAY()))>0),"1級に含む",IF(COUNTIFS('資格研修記録'!$A$5:$A$1004,$A8,'資格研修記録'!$D$5:$D$1004,G$4)=0,"—",IF(COUNTIFS('資格研修記録'!$A$5:$A$1004,$A8,'資格研修記録'!$D$5:$D$1004,G$4,'資格研修記録'!$F$5:$F$1004,"")+COUNTIFS('資格研修記録'!$A$5:$A$1004,$A8,'資格研修記録'!$D$5:$D$1004,G$4,'資格研修記録'!$F$5:$F$1004,">="&TODAY())>0,"○","× 期限切れ")))) | H8: =IF(OR($A8="",H$4=""),"",IF(AND(H$4="小型船舶2級",(COUNTIFS('資格研修記録'!$A$5:$A$1004,$A8,'資格研修記録'!$D$5:$D$1004,"小型船舶1級",'資格研修記録'!$F$5:$F$1004,"")+COUNTIFS('資格研修記録'!$A$5:$A$1004,$A8,'資格研修記録'!$D$5:$D$1004,"小型船舶1級",'資格研修記録'!$F$5:$F$1004,">="&TODAY()))>0),"1級に含む",IF(COUNTIFS('資格研修記録'!$A$5:$A$1004,$A8,'資格研修記録'!$D$5:$D$1004,H$4)=0,"—",IF(COUNTIFS('資格研修記録'!$A$5:$A$1004,$A8,'資格研修記録'!$D$5:$D$1004,H$4,'資格研修記録'!$F$5:$F$1004,"")+COUNTIFS('資格研修記録'!$A$5:$A$1004,$A8,'資格研修記録'!$D$5:$D$1004,H$4,'資格研修記録'!$F$5:$F$1004,">="&TODAY())>0,"○","× 期限切れ")))) | I8: =IF(OR($A8="",I$4=""),"",IF(AND(I$4="小型船舶2級",(COUNTIFS('資格研修記録'!$A$5:$A$1004,$A8,'資格研修記録'!$D$5:$D$1004,"小型船舶1級",'資格研修記録'!$F$5:$F$1004,"")+COUNTIFS('資格研修記録'!$A$5:$A$1004,$A8,'資格研修記録'!$D$5:$D$1004,"小型船舶1級",'資格研修記録'!$F$5:$F$1004,">="&TODAY()))>0),"1級に含む",IF(COUNTIFS('資格研修記録'!$A$5:$A$1004,$A8,'資格研修記録'!$D$5:$D$1004,I$4)=0,"—",IF(COUNTIFS('資格研修記録'!$A$5:$A$1004,$A8,'資格研修記録'!$D$5:$D$1004,I$4,'資格研修記録'!$F$5:$F$1004,"")+COUNTIFS('資格研修記録'!$A$5:$A$1004,$A8,'資格研修記録'!$D$5:$D$1004,I$4,'資格研修記録'!$F$5:$F$1004,">="&TODAY())>0,"○","× 期限切れ")))) | J8: =IF(OR($A8="",J$4=""),"",IF(AND(J$4="小型船舶2級",(COUNTIFS('資格研修記録'!$A$5:$A$1004,$A8,'資格研修記録'!$D$5:$D$1004,"小型船舶1級",'資格研修記録'!$F$5:$F$1004,"")+COUNTIFS('資格研修記録'!$A$5:$A$1004,$A8,'資格研修記録'!$D$5:$D$1004,"小型船舶1級",'資格研修記録'!$F$5:$F$1004,">="&TODAY()))>0),"1級に含む",IF(COUNTIFS('資格研修記録'!$A$5:$A$1004,$A8,'資格研修記録'!$D$5:$D$1004,J$4)=0,"—",IF(COUNTIFS('資格研修記録'!$A$5:$A$1004,$A8,'資格研修記録'!$D$5:$D$1004,J$4,'資格研修記録'!$F$5:$F$1004,"")+COUNTIFS('資格研修記録'!$A$5:$A$1004,$A8,'資格研修記録'!$D$5:$D$1004,J$4,'資格研修記録'!$F$5:$F$1004,">="&TODAY())>0,"○","× 期限切れ")))) | K8: =IF(OR($A8="",K$4=""),"",IF(AND(K$4="小型船舶2級",(COUNTIFS('資格研修記録'!$A$5:$A$1004,$A8,'資格研修記録'!$D$5:$D$1004,"小型船舶1級",'資格研修記録'!$F$5:$F$1004,"")+COUNTIFS('資格研修記録'!$A$5:$A$1004,$A8,'資格研修記録'!$D$5:$D$1004,"小型船舶1級",'資格研修記録'!$F$5:$F$1004,">="&TODAY()))>0),"1級に含む",IF(COUNTIFS('資格研修記録'!$A$5:$A$1004,$A8,'資格研修記録'!$D$5:$D$1004,K$4)=0,"—",IF(COUNTIFS('資格研修記録'!$A$5:$A$1004,$A8,'資格研修記録'!$D$5:$D$1004,K$4,'資格研修記録'!$F$5:$F$1004,"")+COUNTIFS('資格研修記録'!$A$5:$A$1004,$A8,'資格研修記録'!$D$5:$D$1004,K$4,'資格研修記録'!$F$5:$F$1004,">="&TODAY())>0,"○","× 期限切れ")))) | L8: =IF(OR($A8="",L$4=""),"",IF(AND(L$4="小型船舶2級",(COUNTIFS('資格研修記録'!$A$5:$A$1004,$A8,'資格研修記録'!$D$5:$D$1004,"小型船舶1級",'資格研修記録'!$F$5:$F$1004,"")+COUNTIFS('資格研修記録'!$A$5:$A$1004,$A8,'資格研修記録'!$D$5:$D$1004,"小型船舶1級",'資格研修記録'!$F$5:$F$1004,">="&TODAY()))>0),"1級に含む",IF(COUNTIFS('資格研修記録'!$A$5:$A$1004,$A8,'資格研修記録'!$D$5:$D$1004,L$4)=0,"—",IF(COUNTIFS('資格研修記録'!$A$5:$A$1004,$A8,'資格研修記録'!$D$5:$D$1004,L$4,'資格研修記録'!$F$5:$F$1004,"")+COUNTIFS('資格研修記録'!$A$5:$A$1004,$A8,'資格研修記録'!$D$5:$D$1004,L$4,'資格研修記録'!$F$5:$F$1004,">="&TODAY())>0,"○","× 期限切れ"))))
A9: =IF('隊員マスタ'!A9="","",'隊員マスタ'!A9) | B9: =IF(A9="","",'隊員マスタ'!B9) | C9: =IF(A9="","",'隊員マスタ'!C9) | D9: =IF(A9="","",'隊員マスタ'!D9) | E9: =IF(OR($A9="",E$4=""),"",IF(AND(E$4="小型船舶2級",(COUNTIFS('資格研修記録'!$A$5:$A$1004,$A9,'資格研修記録'!$D$5:$D$1004,"小型船舶1級",'資格研修記録'!$F$5:$F$1004,"")+COUNTIFS('資格研修記録'!$A$5:$A$1004,$A9,'資格研修記録'!$D$5:$D$1004,"小型船舶1級",'資格研修記録'!$F$5:$F$1004,">="&TODAY()))>0),"1級に含む",IF(COUNTIFS('資格研修記録'!$A$5:$A$1004,$A9,'資格研修記録'!$D$5:$D$1004,E$4)=0,"—",IF(COUNTIFS('資格研修記録'!$A$5:$A$1004,$A9,'資格研修記録'!$D$5:$D$1004,E$4,'資格研修記録'!$F$5:$F$1004,"")+COUNTIFS('資格研修記録'!$A$5:$A$1004,$A9,'資格研修記録'!$D$5:$D$1004,E$4,'資格研修記録'!$F$5:$F$1004,">="&TODAY())>0,"○","× 期限切れ")))) | F9: =IF(OR($A9="",F$4=""),"",IF(AND(F$4="小型船舶2級",(COUNTIFS('資格研修記録'!$A$5:$A$1004,$A9,'資格研修記録'!$D$5:$D$1004,"小型船舶1級",'資格研修記録'!$F$5:$F$1004,"")+COUNTIFS('資格研修記録'!$A$5:$A$1004,$A9,'資格研修記録'!$D$5:$D$1004,"小型船舶1級",'資格研修記録'!$F$5:$F$1004,">="&TODAY()))>0),"1級に含む",IF(COUNTIFS('資格研修記録'!$A$5:$A$1004,$A9,'資格研修記録'!$D$5:$D$1004,F$4)=0,"—",IF(COUNTIFS('資格研修記録'!$A$5:$A$1004,$A9,'資格研修記録'!$D$5:$D$1004,F$4,'資格研修記録'!$F$5:$F$1004,"")+COUNTIFS('資格研修記録'!$A$5:$A$1004,$A9,'資格研修記録'!$D$5:$D$1004,F$4,'資格研修記録'!$F$5:$F$1004,">="&TODAY())>0,"○","× 期限切れ")))) | G9: =IF(OR($A9="",G$4=""),"",IF(AND(G$4="小型船舶2級",(COUNTIFS('資格研修記録'!$A$5:$A$1004,$A9,'資格研修記録'!$D$5:$D$1004,"小型船舶1級",'資格研修記録'!$F$5:$F$1004,"")+COUNTIFS('資格研修記録'!$A$5:$A$1004,$A9,'資格研修記録'!$D$5:$D$1004,"小型船舶1級",'資格研修記録'!$F$5:$F$1004,">="&TODAY()))>0),"1級に含む",IF(COUNTIFS('資格研修記録'!$A$5:$A$1004,$A9,'資格研修記録'!$D$5:$D$1004,G$4)=0,"—",IF(COUNTIFS('資格研修記録'!$A$5:$A$1004,$A9,'資格研修記録'!$D$5:$D$1004,G$4,'資格研修記録'!$F$5:$F$1004,"")+COUNTIFS('資格研修記録'!$A$5:$A$1004,$A9,'資格研修記録'!$D$5:$D$1004,G$4,'資格研修記録'!$F$5:$F$1004,">="&TODAY())>0,"○","× 期限切れ")))) | H9: =IF(OR($A9="",H$4=""),"",IF(AND(H$4="小型船舶2級",(COUNTIFS('資格研修記録'!$A$5:$A$1004,$A9,'資格研修記録'!$D$5:$D$1004,"小型船舶1級",'資格研修記録'!$F$5:$F$1004,"")+COUNTIFS('資格研修記録'!$A$5:$A$1004,$A9,'資格研修記録'!$D$5:$D$1004,"小型船舶1級",'資格研修記録'!$F$5:$F$1004,">="&TODAY()))>0),"1級に含む",IF(COUNTIFS('資格研修記録'!$A$5:$A$1004,$A9,'資格研修記録'!$D$5:$D$1004,H$4)=0,"—",IF(COUNTIFS('資格研修記録'!$A$5:$A$1004,$A9,'資格研修記録'!$D$5:$D$1004,H$4,'資格研修記録'!$F$5:$F$1004,"")+COUNTIFS('資格研修記録'!$A$5:$A$1004,$A9,'資格研修記録'!$D$5:$D$1004,H$4,'資格研修記録'!$F$5:$F$1004,">="&TODAY())>0,"○","× 期限切れ")))) | I9: =IF(OR($A9="",I$4=""),"",IF(AND(I$4="小型船舶2級",(COUNTIFS('資格研修記録'!$A$5:$A$1004,$A9,'資格研修記録'!$D$5:$D$1004,"小型船舶1級",'資格研修記録'!$F$5:$F$1004,"")+COUNTIFS('資格研修記録'!$A$5:$A$1004,$A9,'資格研修記録'!$D$5:$D$1004,"小型船舶1級",'資格研修記録'!$F$5:$F$1004,">="&TODAY()))>0),"1級に含む",IF(COUNTIFS('資格研修記録'!$A$5:$A$1004,$A9,'資格研修記録'!$D$5:$D$1004,I$4)=0,"—",IF(COUNTIFS('資格研修記録'!$A$5:$A$1004,$A9,'資格研修記録'!$D$5:$D$1004,I$4,'資格研修記録'!$F$5:$F$1004,"")+COUNTIFS('資格研修記録'!$A$5:$A$1004,$A9,'資格研修記録'!$D$5:$D$1004,I$4,'資格研修記録'!$F$5:$F$1004,">="&TODAY())>0,"○","× 期限切れ")))) | J9: =IF(OR($A9="",J$4=""),"",IF(AND(J$4="小型船舶2級",(COUNTIFS('資格研修記録'!$A$5:$A$1004,$A9,'資格研修記録'!$D$5:$D$1004,"小型船舶1級",'資格研修記録'!$F$5:$F$1004,"")+COUNTIFS('資格研修記録'!$A$5:$A$1004,$A9,'資格研修記録'!$D$5:$D$1004,"小型船舶1級",'資格研修記録'!$F$5:$F$1004,">="&TODAY()))>0),"1級に含む",IF(COUNTIFS('資格研修記録'!$A$5:$A$1004,$A9,'資格研修記録'!$D$5:$D$1004,J$4)=0,"—",IF(COUNTIFS('資格研修記録'!$A$5:$A$1004,$A9,'資格研修記録'!$D$5:$D$1004,J$4,'資格研修記録'!$F$5:$F$1004,"")+COUNTIFS('資格研修記録'!$A$5:$A$1004,$A9,'資格研修記録'!$D$5:$D$1004,J$4,'資格研修記録'!$F$5:$F$1004,">="&TODAY())>0,"○","× 期限切れ")))) | K9: =IF(OR($A9="",K$4=""),"",IF(AND(K$4="小型船舶2級",(COUNTIFS('資格研修記録'!$A$5:$A$1004,$A9,'資格研修記録'!$D$5:$D$1004,"小型船舶1級",'資格研修記録'!$F$5:$F$1004,"")+COUNTIFS('資格研修記録'!$A$5:$A$1004,$A9,'資格研修記録'!$D$5:$D$1004,"小型船舶1級",'資格研修記録'!$F$5:$F$1004,">="&TODAY()))>0),"1級に含む",IF(COUNTIFS('資格研修記録'!$A$5:$A$1004,$A9,'資格研修記録'!$D$5:$D$1004,K$4)=0,"—",IF(COUNTIFS('資格研修記録'!$A$5:$A$1004,$A9,'資格研修記録'!$D$5:$D$1004,K$4,'資格研修記録'!$F$5:$F$1004,"")+COUNTIFS('資格研修記録'!$A$5:$A$1004,$A9,'資格研修記録'!$D$5:$D$1004,K$4,'資格研修記録'!$F$5:$F$1004,">="&TODAY())>0,"○","× 期限切れ")))) | L9: =IF(OR($A9="",L$4=""),"",IF(AND(L$4="小型船舶2級",(COUNTIFS('資格研修記録'!$A$5:$A$1004,$A9,'資格研修記録'!$D$5:$D$1004,"小型船舶1級",'資格研修記録'!$F$5:$F$1004,"")+COUNTIFS('資格研修記録'!$A$5:$A$1004,$A9,'資格研修記録'!$D$5:$D$1004,"小型船舶1級",'資格研修記録'!$F$5:$F$1004,">="&TODAY()))>0),"1級に含む",IF(COUNTIFS('資格研修記録'!$A$5:$A$1004,$A9,'資格研修記録'!$D$5:$D$1004,L$4)=0,"—",IF(COUNTIFS('資格研修記録'!$A$5:$A$1004,$A9,'資格研修記録'!$D$5:$D$1004,L$4,'資格研修記録'!$F$5:$F$1004,"")+COUNTIFS('資格研修記録'!$A$5:$A$1004,$A9,'資格研修記録'!$D$5:$D$1004,L$4,'資格研修記録'!$F$5:$F$1004,">="&TODAY())>0,"○","× 期限切れ"))))
